Workbook

Sheet Petunjuk
A1: Analisis Lari & Kesiapan GTR Ultra 30K
A2: Harist - data 11 Juli s/d 14 September 2026 - disusun 17 September 2026
A4: ISI WORKBOOK
A5: Komparatif | B5: Tabel master 18 aktivitas - semua metrik, satu baris per sesi. Semua tab lain menarik angka dari sini.
A6: Tren Periode | B6: Perbandingan agregat Juli vs Agustus vs September. Menjawab: apa yang berubah antar bulan.
A7: Analisis Performa | B7: Pendalaman: dekomposisi cadence x stride, efisiensi, progres per metrik, bentuk split.
A8: Detail Lap | B8: Split per kilometer dari 8 sesi yang punya data lap.
A9: Kesiapan GTR | B9: Skor kesiapan terhadap kebutuhan lomba, per dimensi, dengan bobot yang bisa diubah.
A10: Proyeksi GTR | B10: Tiga skenario waktu finis dan rencana water station. Sel kuning bisa diubah.
A12: CARA BACA
A13: Sel kuning | B13: Input yang boleh diubah. Angka lain ikut menyesuaikan otomatis.
A14: Teks biru | B14: Angka input atau asumsi, bukan hasil hitungan.
A15: Teks hitam | B15: Hasil formula.
A16: Sel kosong | B16: Alat tidak melaporkan metrik itu - bukan nol, tapi tidak ada data.
A18: PERINGATAN DATA
A19: Lintas alat | B19: Pace, jarak, HR, dan cadence sebanding antara Garmin dan COROS. GCT, Vertical Oscillation, Vertical Ratio, dan Power TIDAK sebanding - algoritma dan penempatan sensor berbeda (selisih 24-56 persen).
A20: Stride | B20: Garmin melaporkan stride; COROS tidak. Kolom 'Stride hitung' adalah formula (jarak / waktu / cadence) yang berlaku untuk semua baris, jadi bisa dibandingkan lintas alat.
A21: Best km | B21: Nilai 19 Jul (5:46/km) dan 28 Jul (4:18/km) adalah artefak GPS - tidak dipakai dalam analisis.
A22: Treadmill | B22: Sesi 11 Juli tidak terkalibrasi: jarak, pace, stride, dan vertical ratio diragukan.
A23: Dikecualikan | B23: Sesi 18 Agu (6,40 km), 26 Jul (long walk), 30 Agu (hiking), dan 11 Jul (treadmill) dikeluarkan dari rata-rata pace lari 5K.

Sheet Komparatif
A1: Tabel Komparatif - 18 Aktivitas
A2: Satu baris per sesi. Sel kosong berarti alat tidak melaporkan metrik tersebut.
A4: No | B4: Tanggal | C4: Bulan | D4: Jam | E4: Nama Aktivitas | F4: Tipe | G4: Alat | H4: Jarak (km) | I4: Waktu | J4: Pace /km | K4: Best km | L4: Waktu Lari | M4: Waktu Jalan | N4: % Jalan | O4: HR | P4: HR maks | Q4: Cadence | R4: Cad maks | S4: Stride lapor (m) | T4: Stride hitung (m) | U4: GCT (ms) | V4: Vert Osc (cm) | W4: Vert Ratio (%) | X4: Power (W) | Y4: Aerobic TE | Z4: Suhu (C) | AA4: Elev + (m) | AB4: Elev - (m) | AC4: Kalori | AD4: Keringat (ml) | AE4: Load | AF4: Body Batt | AG4: RPE | AH4: Efisiensi | AI4: Jarak Road | AJ4: Waktu Total | AK4: Catatan
A5: 1 | B5: 46214 | C5: Jul | D5: - | E5: Treadmill Run | F5: Treadmill | G5: Garmin | H5: 2.99 | I5: 0.016597222 | J5: 0.0055324074 | L5: 0.011284722 | M5: 0.0015625 | N5: =IF(OR(L5="",M5=""),"",M5/(L5+M5)) | O5: 137 | P5: 160 | Q5: 114 | R5: 180 | S5: 1.13 | T5: =IF(OR(Q5="",I5=""),"",ROUND(H5*1000/(I5*1440)/Q5,3)) | U5: 292 | V5: 9.8 | W5: 8.7 | X5: 218 | Y5: 2.5 | Z5: 26.4 | AA5: 0 | AB5: 0 | AC5: 188 | AD5: 311 | AF5: -8 | AG5: 1/10 | AH5: =IF(OR(O5="",I5=""),"",ROUND(H5*1000/(I5*1440)/O5,3)) | AI5: =IF(F5="Road",H5,"") | AJ5: 0.016597222 | AK5: Kalibrasi treadmill tidak terverifikasi
A6: 2 | B6: 46222 | C6: Jul | D6: - | E6: Jakarta Run | F6: Road | G6: Garmin | H6: 4.65 | I6: 0.038113426 | J6: 0.0081944444 | K6: 0.0040046296 | L6: 0.015439815 | M6: 0.022592593 | N6: =IF(OR(L6="",M6=""),"",M6/(L6+M6)) | O6: 135 | P6: 165 | Q6: 127 | R6: 163 | S6: 0.69 | T6: =IF(OR(Q6="",I6=""),"",ROUND(H6*1000/(I6*1440)/Q6,3)) | U6: 319 | V6: 6.5 | W6: 10.5 | X6: 136 | Y6: 2.2 | Z6: 31.6 | AA6: 9 | AB6: 1 | AC6: 317 | AD6: 596 | AF6: -8 | AG6: 1/10 | AH6: =IF(OR(O6="",I6=""),"",ROUND(H6*1000/(I6*1440)/O6,3)) | AI6: =IF(F6="Road",H6,"") | AJ6: 0.038113426 | AK6: Best km artefak GPS
A7: 3 | B7: 46224 | C7: Jul | D7: - | E7: Jakarta Run | F7: Road | G7: Garmin | H7: 5.18 | I7: 0.04494213 | J7: 0.0086574074 | K7: 0.0054166667 | L7: 0.01099537 | M7: 0.033796296 | N7: =IF(OR(L7="",M7=""),"",M7/(L7+M7)) | O7: 132 | P7: 162 | Q7: 123 | R7: 163 | S7: 0.68 | T7: =IF(OR(Q7="",I7=""),"",ROUND(H7*1000/(I7*1440)/Q7,3)) | U7: 310 | V7: 6.2 | W7: 9.9 | X7: 123 | Y7: 2 | Z7: 31.3 | AA7: 0 | AB7: 5 | AC7: 343 | AD7: 645 | AF7: -6 | AG7: 7/10 | AH7: =IF(OR(O7="",I7=""),"",ROUND(H7*1000/(I7*1440)/O7,3)) | AI7: =IF(F7="Road",H7,"") | AJ7: 0.050196759 | AK7: Titik terendah - RPE 7/10
A8: 4 | B8: 46229 | C8: Jul | D8: - | E8: Long Walk | F8: Hiking | G8: Garmin | H8: 7.74 | I8: 0.075104167 | J8: 0.0096990741 | K8: 0.0050462963 | L8: 0.015636574 | M8: 0.057280093 | N8: =IF(OR(L8="",M8=""),"",M8/(L8+M8)) | O8: 126 | P8: 162 | Q8: 109 | R8: 165 | S8: 0.69 | T8: =IF(OR(Q8="",I8=""),"",ROUND(H8*1000/(I8*1440)/Q8,3)) | U8: 320 | V8: 6.1 | W8: 10.3 | X8: 106 | Y8: 2.1 | Z8: 30 | AA8: 23 | AB8: 34 | AC8: 516 | AD8: 930 | AF8: -9 | AG8: 1/10 | AH8: =IF(OR(O8="",I8=""),"",ROUND(H8*1000/(I8*1440)/O8,3)) | AI8: =IF(F8="Road",H8,"") | AJ8: 0.095972222 | AK8: Jalan jauh, bukan sesi lari
A9: 5 | B9: 46231 | C9: Jul | D9: - | E9: Jakarta Run | F9: Road | G9: Garmin | H9: 5.13 | I9: 0.041712963 | J9: 0.008125 | K9: 0.0029861111 | L9: 0.016342593 | M9: 0.025266204 | N9: =IF(OR(L9="",M9=""),"",M9/(L9+M9)) | O9: 131 | P9: 159 | Q9: 126 | R9: 170 | S9: 0.71 | T9: =IF(OR(Q9="",I9=""),"",ROUND(H9*1000/(I9*1440)/Q9,3)) | U9: 304 | V9: 6.5 | W9: 10.2 | X9: 137 | Y9: 2.1 | Z9: 29.9 | AA9: 2 | AB9: 6 | AC9: 337 | AD9: 657 | AF9: -3 | AG9: 1/10 | AH9: =IF(OR(O9="",I9=""),"",ROUND(H9*1000/(I9*1440)/O9,3)) | AI9: =IF(F9="Road",H9,"") | AJ9: 0.044664352 | AK9: Best km artefak GPS
A10: 6 | B10: 46238 | C10: Agu | D10: - | E10: Jakarta Run | F10: Road | G10: Garmin | H10: 5.02 | I10: 0.033125 | J10: 0.0066087963 | K10: 0.0046296296 | L10: 0.021631944 | M10: 0.011493056 | N10: =IF(OR(L10="",M10=""),"",M10/(L10+M10)) | O10: 150 | P10: 166 | Q10: 144 | R10: 183 | S10: 0.71 | T10: =IF(OR(Q10="",I10=""),"",ROUND(H10*1000/(I10*1440)/Q10,3)) | U10: 304 | V10: 7 | W10: 9.9 | X10: 177 | Y10: 2.5 | Z10: 30 | AA10: 14 | AB10: 6 | AC10: 358 | AD10: 674 | AF10: -7 | AH10: =IF(OR(O10="",I10=""),"",ROUND(H10*1000/(I10*1440)/O10,3)) | AI10: =IF(F10="Road",H10,"") | AJ10: 0.033981481 | AK10: Lompatan besar dari Juli
A11: 7 | B11: 46240 | C11: Agu | D11: - | E11: Jakarta Run | F11: Road | G11: Garmin | H11: 5.02 | I11: 0.03380787 | J11: 0.0067361111 | K11: 0.0045601852 | L11: 0.021446759 | M11: 0.012361111 | N11: =IF(OR(L11="",M11=""),"",M11/(L11+M11)) | O11: 150 | P11: 168 | Q11: 142 | R11: 174 | S11: 0.72 | T11: =IF(OR(Q11="",I11=""),"",ROUND(H11*1000/(I11*1440)/Q11,3)) | U11: 297 | V11: 7 | W11: 10 | X11: 173 | Y11: 2.5 | Z11: 31.7 | AA11: 4 | AB11: 6 | AC11: 354 | AD11: 674 | AF11: -7 | AH11: =IF(OR(O11="",I11=""),"",ROUND(H11*1000/(I11*1440)/O11,3)) | AI11: =IF(F11="Road",H11,"") | AJ11: 0.03380787 | AK11: Positive split, sebaran 67 dtk
A12: 8 | B12: 46245 | C12: Agu | D12: - | E12: Jakarta Run | F12: Road | G12: Garmin | H12: 5.02 | I12: 0.033599537 | J12: 0.0066898148 | K12: 0.004525463 | L12: 0.027349537 | M12: 0.00625 | N12: =IF(OR(L12="",M12=""),"",M12/(L12+M12)) | O12: 153 | P12: 169 | Q12: 143 | R12: 171 | S12: 0.72 | T12: =IF(OR(Q12="",I12=""),"",ROUND(H12*1000/(I12*1440)/Q12,3)) | U12: 305 | V12: 7.4 | W12: 10.7 | X12: 180 | Y12: 2.4 | Z12: 31.1 | AA12: 5 | AB12: 7 | AC12: 351 | AD12: 696 | AF12: -6 | AH12: =IF(OR(O12="",I12=""),"",ROUND(H12*1000/(I12*1440)/O12,3)) | AI12: =IF(F12="Road",H12,"") | AJ12: 0.033599537 | AK12: Walk time tembus di bawah 10 mnt
A13: 9 | B13: 46247 | C13: Agu | D13: - | E13: Jakarta Run | F13: Road | G13: Garmin | H13: 5.01 | I13: 0.03306713 | J13: 0.0065972222 | K13: 0.0045601852 | L13: 0.027233796 | M13: 0.0057986111 | N13: =IF(OR(L13="",M13=""),"",M13/(L13+M13)) | O13: 154 | P13: 168 | Q13: 140 | R13: 171 | S13: 0.74 | T13: =IF(OR(Q13="",I13=""),"",ROUND(H13*1000/(I13*1440)/Q13,3)) | U13: 299 | V13: 7.6 | W13: 10.7 | X13: 183 | Y13: 2.7 | Z13: 31.1 | AA13: 4 | AB13: 4 | AC13: 357 | AD13: 691 | AF13: -3 | AH13: =IF(OR(O13="",I13=""),"",ROUND(H13*1000/(I13*1440)/O13,3)) | AI13: =IF(F13="Road",H13,"") | AJ13: 0.03306713 | AK13: Stride tertinggi era Garmin
A14: 10 | B14: 46252 | C14: Agu | D14: - | E14: Jakarta Long Run | F14: Road | G14: Garmin | H14: 6.4 | I14: 0.050219907 | J14: 0.0078472222 | K14: 0.0048611111 | L14: 0.027048611 | M14: 0.023020833 | N14: =IF(OR(L14="",M14=""),"",M14/(L14+M14)) | O14: 133 | P14: 162 | Q14: 129 | R14: 176 | S14: 0.69 | T14: =IF(OR(Q14="",I14=""),"",ROUND(H14*1000/(I14*1440)/Q14,3)) | U14: 309 | V14: 6.7 | W14: 10.7 | X14: 146 | Y14: 2.3 | Z14: 31.6 | AA14: 7 | AB14: 11 | AC14: 425 | AD14: 915 | AF14: -7 | AG14: 1/10 | AH14: =IF(OR(O14="",I14=""),"",ROUND(H14*1000/(I14*1440)/O14,3)) | AI14: =IF(F14="Road",H14,"") | AJ14: 0.057025463 | AK14: Rute 6,4 km - pace tidak sebanding
A15: 11 | B15: 46254 | C15: Agu | D15: - | E15: Jakarta Run | F15: Road | G15: Garmin | H15: 5.02 | I15: 0.031597222 | J15: 0.0062962963 | K15: 0.0045601852 | L15: 0.02681713 | M15: 0.0046990741 | N15: =IF(OR(L15="",M15=""),"",M15/(L15+M15)) | O15: 157 | P15: 168 | Q15: 157 | R15: 187 | S15: 0.69 | T15: =IF(OR(Q15="",I15=""),"",ROUND(H15*1000/(I15*1440)/Q15,3)) | U15: 286 | V15: 7.1 | W15: 10.4 | X15: 192 | Y15: 2.6 | Z15: 31.4 | AA15: 2 | AB15: 4 | AC15: 346 | AD15: 720 | AF15: -5 | AG15: 3/10 | AH15: =IF(OR(O15="",I15=""),"",ROUND(H15*1000/(I15*1440)/O15,3)) | AI15: =IF(F15="Road",H15,"") | AJ15: 0.031597222 | AK15: Cadence lompat 140-157, stride jatuh
A16: 12 | B16: 46260 | C16: Agu | D16: 05:18 | E16: West Jakarta Run | F16: Road | G16: COROS | H16: 5.02 | I16: 0.030428241 | J16: 0.0060648148 | K16: 0.0054282407 | N16: =IF(OR(L16="",M16=""),"",M16/(L16+M16)) | O16: 153 | Q16: 162 | R16: 179 | T16: =IF(OR(Q16="",I16=""),"",ROUND(H16*1000/(I16*1440)/Q16,3)) | X16: 85 | Y16: 3 | Z16: 26 | AA16: 2 | AB16: 7 | AC16: 286 | AE16: 94 | AH16: =IF(OR(O16="",I16=""),"",ROUND(H16*1000/(I16*1440)/O16,3)) | AI16: =IF(F16="Road",H16,"") | AJ16: 0.030428241 | AK16: Satu-satunya sesi di bawah 29 C. Negative split
A17: 13 | B17: 46264 | C17: Agu | D17: 10:49 | E17: Wonosobo Regency Trail | F17: Hiking | G17: COROS | H17: 8.13 | I17: 0.19953704 | J17: 0.024548611 | K17: 0.010949074 | N17: =IF(OR(L17="",M17=""),"",M17/(L17+M17)) | O17: 117 | Q17: 67 | T17: =IF(OR(Q17="",I17=""),"",ROUND(H17*1000/(I17*1440)/Q17,3)) | X17: 45 | Y17: 2.8 | AA17: 516 | AB17: 681 | AC17: 1954 | AE17: 98 | AH17: =IF(OR(O17="",I17=""),"",ROUND(H17*1000/(I17*1440)/O17,3)) | AI17: =IF(F17="Road",H17,"") | AJ17: 0.26787037 | AK17: Turunan 681 m - pemicu DOMS 1 Sep
A18: 14 | B18: 46266 | C18: Sep | D18: 19:30 | E18: Central Jakarta Run | F18: Road | G18: COROS | H18: 5.01 | I18: 0.032025463 | J18: 0.0063888889 | K18: 0.0054398148 | N18: =IF(OR(L18="",M18=""),"",M18/(L18+M18)) | O18: 149 | Q18: 152 | T18: =IF(OR(Q18="",I18=""),"",ROUND(H18*1000/(I18*1440)/Q18,3)) | X18: 142 | Y18: 2.9 | AA18: 3 | AB18: 4 | AC18: 492 | AE18: 88 | AH18: =IF(OR(O18="",I18=""),"",ROUND(H18*1000/(I18*1440)/O18,3)) | AI18: =IF(F18="Road",H18,"") | AJ18: 0.051423611 | AK18: Kolaps DOMS 48 jam pasca Wonosobo
A19: 15 | B19: 46268 | C19: Sep | D19: 20:24 | E19: Jakarta Run | F19: Road | G19: COROS | H19: 5.03 | I19: 0.029652778 | J19: 0.0058912037 | K19: 0.0054976852 | N19: =IF(OR(L19="",M19=""),"",M19/(L19+M19)) | O19: 157 | Q19: 168 | R19: 173 | T19: =IF(OR(Q19="",I19=""),"",ROUND(H19*1000/(I19*1440)/Q19,3)) | X19: 150 | Y19: 3.2 | AA19: 6 | AB19: 5 | AC19: 495 | AE19: 108 | AH19: =IF(OR(O19="",I19=""),"",ROUND(H19*1000/(I19*1440)/O19,3)) | AI19: =IF(F19="Road",H19,"") | AJ19: 0.029652778 | AK19: PR sebelumnya. Negative split
A20: 16 | B20: 46271 | C20: Sep | D20: 17:06 | E20: Jakarta Run | F20: Road | G20: COROS | H20: 5.03 | I20: 0.029976852 | J20: 0.0059606481 | K20: 0.0055787037 | N20: =IF(OR(L20="",M20=""),"",M20/(L20+M20)) | O20: 159 | Q20: 167 | R20: 170 | T20: =IF(OR(Q20="",I20=""),"",ROUND(H20*1000/(I20*1440)/Q20,3)) | X20: 150 | Y20: 3.3 | AA20: 0 | AB20: 3 | AC20: 422 | AE20: 115 | AH20: =IF(OR(O20="",I20=""),"",ROUND(H20*1000/(I20*1440)/O20,3)) | AI20: =IF(F20="Road",H20,"") | AJ20: 0.029976852 | AK20: Lebih lambat + HR naik = decoupling
A21: 17 | B21: 46275 | C21: Sep | D21: 19:03 | E21: Jakarta Special Capital Region Run | F21: Road | G21: COROS | H21: 5.02 | I21: 0.030158102 | J21: 0.0060069444 | K21: 0.0056944444 | N21: =IF(OR(L21="",M21=""),"",M21/(L21+M21)) | O21: 159 | Q21: 161 | T21: =IF(OR(Q21="",I21=""),"",ROUND(H21*1000/(I21*1440)/Q21,3)) | X21: 148 | Y21: 3.3 | AA21: 7 | AB21: 3 | AC21: 426 | AE21: 117 | AH21: =IF(OR(O21="",I21=""),"",ROUND(H21*1000/(I21*1440)/O21,3)) | AI21: =IF(F21="Road",H21,"") | AJ21: 0.030158102 | AK21: Base. Pace rata, HR tinggi merata
A22: 18 | B22: 46279 | C22: Sep | D22: 20:01 | E22: Jakarta Run | F22: Road | G22: COROS | H22: 5.01 | I22: 0.027797801 | J22: 0.0055555556 | K22: 0.005 | N22: =IF(OR(L22="",M22=""),"",M22/(L22+M22)) | O22: 157 | Q22: 167 | T22: =IF(OR(Q22="",I22=""),"",ROUND(H22*1000/(I22*1440)/Q22,3)) | X22: 158 | Y22: 3.1 | AA22: 8 | AB22: 10 | AC22: 386 | AE22: 104 | AH22: =IF(OR(O22="",I22=""),"",ROUND(H22*1000/(I22*1440)/O22,3)) | AI22: =IF(F22="Road",H22,"") | AJ22: 0.027797801 | AK22: PR BARU. Tempo. Efficiency 103%
E23: TOTAL / RATA-RATA | H23: =SUM(H5:H22) | I23: =SUM(I5:I22) | AC23: =SUM(AC5:AC22)

Sheet Tren Periode
A1: Tren Antar Periode
A2: Hanya sesi Road (lari jalanan) yang dihitung. Hiking, long walk, dan treadmill dikecualikan.
A4: Metrik | B4: Juli | C4: Agustus | D4: September | E4: Jul ke Sep | F4: Perubahan
A5: Jumlah sesi lari | B5: =COUNTIFS(Komparatif!$C$5:$C$22,"Jul",Komparatif!$F$5:$F$22,"Road") | C5: =COUNTIFS(Komparatif!$C$5:$C$22,"Agu",Komparatif!$F$5:$F$22,"Road") | D5: =COUNTIFS(Komparatif!$C$5:$C$22,"Sep",Komparatif!$F$5:$F$22,"Road") | E5: =IF(OR(B5="",D5=""),"",D5-B5) | F5: =IF(OR(B5="",B5=0,D5=""),"",D5/B5-1)
A6: Jarak total (km) | B6: =SUMIFS(Komparatif!H5:H22,Komparatif!$C$5:$C$22,"Jul",Komparatif!$F$5:$F$22,"Road") | C6: =SUMIFS(Komparatif!H5:H22,Komparatif!$C$5:$C$22,"Agu",Komparatif!$F$5:$F$22,"Road") | D6: =SUMIFS(Komparatif!H5:H22,Komparatif!$C$5:$C$22,"Sep",Komparatif!$F$5:$F$22,"Road") | E6: =IF(OR(B6="",D6=""),"",D6-B6) | F6: =IF(OR(B6="",B6=0,D6=""),"",D6/B6-1)
A7: Pace rata-rata /km | B7: =IFERROR(AVERAGEIFS(Komparatif!J5:J22,Komparatif!$C$5:$C$22,"Jul",Komparatif!$F$5:$F$22,"Road"),"") | C7: =IFERROR(AVERAGEIFS(Komparatif!J5:J22,Komparatif!$C$5:$C$22,"Agu",Komparatif!$F$5:$F$22,"Road"),"") | D7: =IFERROR(AVERAGEIFS(Komparatif!J5:J22,Komparatif!$C$5:$C$22,"Sep",Komparatif!$F$5:$F$22,"Road"),"") | E7: =IF(OR(B7="",D7=""),"",D7-B7) | F7: =IF(OR(B7="",B7=0,D7=""),"",D7/B7-1)
A8: Best km rata-rata | B8: =IFERROR(AVERAGEIFS(Komparatif!K5:K22,Komparatif!$C$5:$C$22,"Jul",Komparatif!$F$5:$F$22,"Road"),"") | C8: =IFERROR(AVERAGEIFS(Komparatif!K5:K22,Komparatif!$C$5:$C$22,"Agu",Komparatif!$F$5:$F$22,"Road"),"") | D8: =IFERROR(AVERAGEIFS(Komparatif!K5:K22,Komparatif!$C$5:$C$22,"Sep",Komparatif!$F$5:$F$22,"Road"),"") | E8: =IF(OR(B8="",D8=""),"",D8-B8) | F8: =IF(OR(B8="",B8=0,D8=""),"",D8/B8-1)
A9: HR rata-rata (bpm) | B9: =IFERROR(AVERAGEIFS(Komparatif!O5:O22,Komparatif!$C$5:$C$22,"Jul",Komparatif!$F$5:$F$22,"Road"),"") | C9: =IFERROR(AVERAGEIFS(Komparatif!O5:O22,Komparatif!$C$5:$C$22,"Agu",Komparatif!$F$5:$F$22,"Road"),"") | D9: =IFERROR(AVERAGEIFS(Komparatif!O5:O22,Komparatif!$C$5:$C$22,"Sep",Komparatif!$F$5:$F$22,"Road"),"") | E9: =IF(OR(B9="",D9=""),"",D9-B9) | F9: =IF(OR(B9="",B9=0,D9=""),"",D9/B9-1)
A10: Cadence rata-rata (spm) | B10: =IFERROR(AVERAGEIFS(Komparatif!Q5:Q22,Komparatif!$C$5:$C$22,"Jul",Komparatif!$F$5:$F$22,"Road"),"") | C10: =IFERROR(AVERAGEIFS(Komparatif!Q5:Q22,Komparatif!$C$5:$C$22,"Agu",Komparatif!$F$5:$F$22,"Road"),"") | D10: =IFERROR(AVERAGEIFS(Komparatif!Q5:Q22,Komparatif!$C$5:$C$22,"Sep",Komparatif!$F$5:$F$22,"Road"),"") | E10: =IF(OR(B10="",D10=""),"",D10-B10) | F10: =IF(OR(B10="",B10=0,D10=""),"",D10/B10-1)
A11: Stride rata-rata (m) | B11: =IFERROR(AVERAGEIFS(Komparatif!T5:T22,Komparatif!$C$5:$C$22,"Jul",Komparatif!$F$5:$F$22,"Road"),"") | C11: =IFERROR(AVERAGEIFS(Komparatif!T5:T22,Komparatif!$C$5:$C$22,"Agu",Komparatif!$F$5:$F$22,"Road"),"") | D11: =IFERROR(AVERAGEIFS(Komparatif!T5:T22,Komparatif!$C$5:$C$22,"Sep",Komparatif!$F$5:$F$22,"Road"),"") | E11: =IF(OR(B11="",D11=""),"",D11-B11) | F11: =IF(OR(B11="",B11=0,D11=""),"",D11/B11-1)
A12: Efisiensi (m/mnt per bpm) | B12: =IFERROR(AVERAGEIFS(Komparatif!AH5:AH22,Komparatif!$C$5:$C$22,"Jul",Komparatif!$F$5:$F$22,"Road"),"") | C12: =IFERROR(AVERAGEIFS(Komparatif!AH5:AH22,Komparatif!$C$5:$C$22,"Agu",Komparatif!$F$5:$F$22,"Road"),"") | D12: =IFERROR(AVERAGEIFS(Komparatif!AH5:AH22,Komparatif!$C$5:$C$22,"Sep",Komparatif!$F$5:$F$22,"Road"),"") | E12: =IF(OR(B12="",D12=""),"",D12-B12) | F12: =IF(OR(B12="",B12=0,D12=""),"",D12/B12-1)
A13: Suhu rata-rata (C) | B13: =IFERROR(AVERAGEIFS(Komparatif!Z5:Z22,Komparatif!$C$5:$C$22,"Jul",Komparatif!$F$5:$F$22,"Road"),"") | C13: =IFERROR(AVERAGEIFS(Komparatif!Z5:Z22,Komparatif!$C$5:$C$22,"Agu",Komparatif!$F$5:$F$22,"Road"),"") | D13: =IFERROR(AVERAGEIFS(Komparatif!Z5:Z22,Komparatif!$C$5:$C$22,"Sep",Komparatif!$F$5:$F$22,"Road"),"") | E13: =IF(OR(B13="",D13=""),"",D13-B13) | F13: =IF(OR(B13="",B13=0,D13=""),"",D13/B13-1)
A14: Kalori rata-rata | B14: =IFERROR(AVERAGEIFS(Komparatif!AC5:AC22,Komparatif!$C$5:$C$22,"Jul",Komparatif!$F$5:$F$22,"Road"),"") | C14: =IFERROR(AVERAGEIFS(Komparatif!AC5:AC22,Komparatif!$C$5:$C$22,"Agu",Komparatif!$F$5:$F$22,"Road"),"") | D14: =IFERROR(AVERAGEIFS(Komparatif!AC5:AC22,Komparatif!$C$5:$C$22,"Sep",Komparatif!$F$5:$F$22,"Road"),"") | E14: =IF(OR(B14="",D14=""),"",D14-B14) | F14: =IF(OR(B14="",B14=0,D14=""),"",D14/B14-1)
A16: Untuk Pace dan Best km, angka Perubahan yang negatif berarti MEMBAIK (lebih cepat).
A17: Efisiensi = kecepatan (meter per menit) dibagi HR rata-rata. Makin tinggi makin efisien.

Sheet Analisis Performa
A1: Analisis Performa
A2: Pendalaman: dari mana kecepatan datang, dan apa yang berubah.
A4: A. DEKOMPOSISI KECEPATAN - kecepatan = cadence x stride
A5: Pasangan sesi | B5: Cad awal | C5: Cad akhir | D5: Delta Cadence | E5: Stride awal | F5: Stride akhir | G5: Delta Stride | H5: Delta Kecepatan | I5: Kontribusi stride
A6: 21 Jul ke 14 Sep (seluruh program) | B6: =Komparatif!Q7 | C6: =Komparatif!Q22 | D6: =C6/B6-1 | E6: =Komparatif!T7 | F6: =Komparatif!T22 | G6: =F6/E6-1 | H6: =(C6*F6)/(B6*E6)-1 | I6: =IFERROR(IF(LN(C6/B6)*LN(F6/E6)<0,"faktor berlawanan arah",TEXT(LN(F6/E6)/(LN(C6/B6)+LN(F6/E6)),"0%")),"-")
A7: 6 Sep ke 14 Sep (terobosan stride) | B7: =Komparatif!Q20 | C7: =Komparatif!Q22 | D7: =C7/B7-1 | E7: =Komparatif!T20 | F7: =Komparatif!T22 | G7: =F7/E7-1 | H7: =(C7*F7)/(B7*E7)-1 | I7: =IFERROR(IF(LN(C7/B7)*LN(F7/E7)<0,"faktor berlawanan arah",TEXT(LN(F7/E7)/(LN(C7/B7)+LN(F7/E7)),"0%")),"-")
A8: 10 Sep ke 14 Sep (dua sesi terakhir) | B8: =Komparatif!Q21 | C8: =Komparatif!Q22 | D8: =C8/B8-1 | E8: =Komparatif!T21 | F8: =Komparatif!T22 | G8: =F8/E8-1 | H8: =(C8*F8)/(B8*E8)-1 | I8: =IFERROR(IF(LN(C8/B8)*LN(F8/E8)<0,"faktor berlawanan arah",TEXT(LN(F8/E8)/(LN(C8/B8)+LN(F8/E8)),"0%")),"-")
A9: 13 Agu ke 20 Agu (cadence naik, stride jatuh) | B9: =Komparatif!Q13 | C9: =Komparatif!Q15 | D9: =C9/B9-1 | E9: =Komparatif!T13 | F9: =Komparatif!T15 | G9: =F9/E9-1 | H9: =(C9*F9)/(B9*E9)-1 | I9: =IFERROR(IF(LN(C9/B9)*LN(F9/E9)<0,"faktor berlawanan arah",TEXT(LN(F9/E9)/(LN(C9/B9)+LN(F9/E9)),"0%")),"-")
A10: Kontribusi stride = ln(rasio stride) dibagi ln(rasio total kecepatan). Angka 100% berarti seluruh perbaikan datang dari panjang langkah.
A11: Bila cadence dan stride bergerak berlawanan arah, pembagian kontribusi tidak bermakna - kolom terakhir menandainya.
A13: B. EFISIENSI - kecepatan per denyut jantung
A14: Sesi | B14: Pace /km | C14: HR | D14: Kecepatan (m/mnt) | E14: Efisiensi | I14: Baca
A15: 1 Sep | B15: =Komparatif!J18 | C15: =Komparatif!O18 | D15: =Komparatif!H18*1000/(Komparatif!I18*1440) | E15: =Komparatif!AH18 | I15: =IF(E19=MAX(E15:E19),"Efisiensi tertinggi ada di sesi terakhir (14 Sep).","Efisiensi tertinggi BUKAN di sesi terakhir.")
A16: 3 Sep | B16: =Komparatif!J19 | C16: =Komparatif!O19 | D16: =Komparatif!H19*1000/(Komparatif!I19*1440) | E16: =Komparatif!AH19 | I16: ="Naik "&TEXT(E19/MAX(E15:E18)-1,"0.0%")&" di atas efisiensi terbaik sebelumnya."
A17: 6 Sep | B17: =Komparatif!J20 | C17: =Komparatif!O20 | D17: =Komparatif!H20*1000/(Komparatif!I20*1440) | E17: =Komparatif!AH20
A18: 10 Sep | B18: =Komparatif!J21 | C18: =Komparatif!O21 | D18: =Komparatif!H21*1000/(Komparatif!I21*1440) | E18: =Komparatif!AH21
A19: 14 Sep | B19: =Komparatif!J22 | C19: =Komparatif!O22 | D19: =Komparatif!H22*1000/(Komparatif!I22*1440) | E19: =Komparatif!AH22
A21: C. PROGRES PER METRIK - sesi lari pertama vs terakhir
A22: Metrik | B22: 21 Jul | C22: 14 Sep | D22: Selisih | E22: Perubahan | I22: Status
A23: Waktu 5K | B23: =Komparatif!I7 | C23: =Komparatif!I22 | D23: =C23-B23 | E23: =IF(B23=0,"",C23/B23-1) | I23: =IF(D23<0,"Membaik","Perlu dicek")
A24: Pace /km | B24: =Komparatif!J7 | C24: =Komparatif!J22 | D24: =C24-B24 | E24: =IF(B24=0,"",C24/B24-1) | I24: =IF(D24<0,"Membaik","Perlu dicek")
A25: Best km | B25: =Komparatif!K7 | C25: =Komparatif!K22 | D25: =C25-B25 | E25: =IF(B25=0,"",C25/B25-1) | I25: =IF(D25<0,"Membaik","Perlu dicek")
A26: Cadence (spm) | B26: =Komparatif!Q7 | C26: =Komparatif!Q22 | D26: =C26-B26 | E26: =IF(B26=0,"",C26/B26-1) | I26: =IF(D26>0,"Membaik","Perlu dicek")
A27: Stride hitung (m) | B27: =Komparatif!T7 | C27: =Komparatif!T22 | D27: =C27-B27 | E27: =IF(B27=0,"",C27/B27-1) | I27: =IF(D27>0,"Membaik","Perlu dicek")
A28: HR rata-rata (bpm) | B28: =Komparatif!O7 | C28: =Komparatif!O22 | D28: =C28-B28 | E28: =IF(B28=0,"",C28/B28-1) | I28: =IF(D28>0,"Membaik","Perlu dicek")
A29: Efisiensi | B29: =Komparatif!AH7 | C29: =Komparatif!AH22 | D29: =C29-B29 | E29: =IF(B29=0,"",C29/B29-1) | I29: =IF(D29>0,"Membaik","Perlu dicek")
A30: Aerobic TE | B30: =Komparatif!Y7 | C30: =Komparatif!Y22 | D30: =C30-B30 | E30: =IF(B30=0,"",C30/B30-1) | I30: =IF(D30>0,"Membaik","Perlu dicek")
A32: D. BENTUK SPLIT - melambat atau justru mempercepat di akhir
A33: Sesi | B33: KM tercepat | C33: KM terlambat | D33: Sebaran | E33: Bentuk | I33: Baca
A34: 6 Agu | B34: 0.0063483796 | C34: 0.0071180556 | D34: =C34-B34 | E34: Positive split | I34: Melambat 67 dtk - km 3 titik pecahnya
A35: 26 Agu | B35: 0.0055787037 | C35: 0.0063425926 | D35: =C35-B35 | E35: Negative split | I35: Km terakhir 56 dtk lebih cepat dari km 1
A36: 1 Sep | B36: 0.0057523148 | C36: 0.0074768519 | D36: =C36-B36 | E36: Positive split | I36: Kolaps DOMS - cadence jatuh ke 138 di km 5
A37: 3 Sep | B37: 0.0055208333 | C37: 0.0062731481 | D37: =C37-B37 | E37: Negative split | I37: Km terakhir tercepat (7:57/km)
A38: 6 Sep | B38: 0.0057175926 | C38: 0.0061226852 | D38: =C38-B38 | E38: Cukup rata | I38: Sebaran tersempit - 35 dtk
A39: 10 Sep | B39: 0.005775463 | C39: 0.0062037037 | D39: =C39-B39 | E39: Cukup rata | I39: Sebaran 37 dtk, km tercepat di tengah
A40: 14 Sep | B40: 0.0050231481 | C40: 0.0058564815 | D40: =C40-B40 | E40: Surge di km 4 | I40: Sebaran 72 dtk - km 4 (7:14) jauh di depan
A42: E. TEMUAN UTAMA
A44: 1. Rekor baru 14 Sep: 40:02 untuk 5,01 km - memangkas 2 menit 40 detik dari PR sebelumnya 42:42 (3 Sep).
A45: 2. Stride pecah dari plateau dua bulan: 0,698 m (6 Sep) menjadi 0,750 m (14 Sep), naik 5,2 cm.
A46: 3. Terhadap PR lama 3 Sep, cadence justru TURUN 1 spm. Jadi hampir seluruh perbaikan datang dari stride, bukan frekuensi langkah.
...

Sheet Detail Lap
A1: Detail Lap per Kilometer
A2: 8 sesi yang punya data lap. Lap pecahan (kurang dari 1 km) tidak dihitung pace-nya.
A4: Tanggal | B4: Sesi | C4: Lap | D4: Jarak (km) | E4: Waktu | F4: Pace /km | G4: HR | H4: Cadence | I4: Stride (m) | J4: GCT (ms) | K4: Power (W) | L4: Terbaik
A5: 06/08/2026 | B5: Jakarta Run | C5: 1 | D5: 1 | E5: 0.0063483796 | F5: =IF(D5<0.9,"",E5/D5)
C6: 2 | D6: 1 | E6: 0.0063275463 | F6: =IF(D6<0.9,"",E6/D6)
C7: 3 | D7: 1 | E7: 0.0070613426 | F7: =IF(D7<0.9,"",E7/D7)
C8: 4 | D8: 1 | E8: 0.0067974537 | F8: =IF(D8<0.9,"",E8/D8)
C9: 5 | D9: 1 | E9: 0.0071180556 | F9: =IF(D9<0.9,"",E9/D9)
C10: 6 | D10: 0.02 | E10: 0.00015972222 | F10: =IF(D10<0.9,"",E10/D10)
A11: 26/08/2026 | B11: West Jakarta Run | C11: 1 | D11: 1 | E11: 0.0062268519 | F11: =IF(D11<0.9,"",E11/D11) | G11: 144 | H11: 159 | I11: 0.7 | J11: 317 | K11: 83
C12: 2 | D12: 1 | E12: 0.0063425926 | F12: =IF(D12<0.9,"",E12/D12) | G12: 153 | H12: 165 | I12: 0.66 | J12: 310 | K12: 83
C13: 3 | D13: 1 | E13: 0.0063078704 | F13: =IF(D13<0.9,"",E13/D13) | G13: 152 | H13: 162 | I13: 0.68 | J13: 311 | K13: 82
C14: 4 | D14: 1 | E14: 0.0058564815 | F14: =IF(D14<0.9,"",E14/D14) | G14: 157 | H14: 162 | I14: 0.73 | J14: 304 | K14: 86
C15: 5 | D15: 1 | E15: 0.0055787037 | F15: =IF(D15<0.9,"",E15/D15) | G15: 160 | H15: 162 | I15: 0.77 | J15: 314 | K15: 92 | L15: BEST
C16: 6 | D16: 0.02 | E16: 0.00011574074 | F16: =IF(D16<0.9,"",E16/D16) | G16: 162 | H16: 155 | I16: 0.65 | J16: 308 | K16: 93
A17: 30/08/2026 | B17: Wonosobo Trail | C17: 1 | D17: 1 | E17: 0.035914352 | F17: =IF(D17<0.9,"",E17/D17) | G17: 108
C18: 2 | D18: 1 | E18: 0.031006944 | F18: =IF(D18<0.9,"",E18/D18) | G18: 125
C19: 3 | D19: 1 | E19: 0.016736111 | F19: =IF(D19<0.9,"",E19/D19) | G19: 121
C20: 4 | D20: 1 | E20: 0.019282407 | F20: =IF(D20<0.9,"",E20/D20) | G20: 106
C21: 5 | D21: 1 | E21: 0.012476852 | F21: =IF(D21<0.9,"",E21/D21) | G21: 107 | L21: BEST
C22: 6 | D22: 1 | E22: 0.018784722 | F22: =IF(D22<0.9,"",E22/D22) | G22: 127
C23: 7 | D23: 1 | E23: 0.035833333 | F23: =IF(D23<0.9,"",E23/D23) | G23: 122
C24: 8 | D24: 1 | E24: 0.027083333 | F24: =IF(D24<0.9,"",E24/D24) | G24: 116
C25: 9 | D25: 0.13 | E25: 0.0024074074 | F25: =IF(D25<0.9,"",E25/D25) | G25: 123
A26: 01/09/2026 | B26: Central Jakarta Run | C26: 1 | D26: 1 | E26: 0.0059027778 | F26: =IF(D26<0.9,"",E26/D26) | G26: 148 | H26: 157 | K26: 147
C27: 2 | D27: 1 | E27: 0.0062847222 | F27: =IF(D27<0.9,"",E27/D27) | G27: 150 | H27: 156 | K27: 145
C28: 3 | D28: 1 | E28: 0.0057523148 | F28: =IF(D28<0.9,"",E28/D28) | G28: 156 | H28: 163 | K28: 157 | L28: BEST
C29: 4 | D29: 1 | E29: 0.0065393519 | F29: =IF(D29<0.9,"",E29/D29) | G29: 151 | H29: 149 | K29: 137
C30: 5 | D30: 1 | E30: 0.0074768519 | F30: =IF(D30<0.9,"",E30/D30) | G30: 143 | H30: 138 | K30: 130
C31: 6 | D31: 0.01 | E31: 6.9444444e-05 | F31: =IF(D31<0.9,"",E31/D31) | G31: 155 | H31: 150 | K31: 157
A32: 03/09/2026 | B32: Jakarta Run | C32: 1 | D32: 1 | E32: 0.0062731481 | F32: =IF(D32<0.9,"",E32/D32) | G32: 143 | H32: 169 | K32: 139
C33: 2 | D33: 1 | E33: 0.005775463 | F33: =IF(D33<0.9,"",E33/D33) | G33: 158 | H33: 173 | K33: 150
C34: 3 | D34: 1 | E34: 0.0058912037 | F34: =IF(D34<0.9,"",E34/D34) | G34: 160 | H34: 168 | K34: 147
C35: 4 | D35: 1 | E35: 0.0060185185 | F35: =IF(D35<0.9,"",E35/D35) | G35: 162 | H35: 167 | K35: 155
C36: 5 | D36: 1 | E36: 0.0055208333 | F36: =IF(D36<0.9,"",E36/D36) | G36: 164 | H36: 166 | K36: 161 | L36: BEST
C37: 6 | D37: 0.03 | E37: 0.00018518519 | F37: =IF(D37<0.9,"",E37/D37) | G37: 167 | H37: 168 | K37: 157
A38: 06/09/2026 | B38: Jakarta Run | C38: 1 | D38: 1 | E38: 0.0057175926 | F38: =IF(D38<0.9,"",E38/D38) | G38: 147 | H38: 164 | K38: 151 | L38: BEST
C39: 2 | D39: 1 | E39: 0.0059375 | F39: =IF(D39<0.9,"",E39/D39) | G39: 160 | H39: 170 | K39: 158
C40: 3 | D40: 1 | E40: 0.0060069444 | F40: =IF(D40<0.9,"",E40/D40) | G40: 161 | H40: 168 | K40: 149
C41: 4 | D41: 1 | E41: 0.0061226852 | F41: =IF(D41<0.9,"",E41/D41) | G41: 161 | H41: 168 | K41: 146
...

Sheet Kesiapan GTR
A1: Kesiapan GTR Ultra 30K - Dalam Angka
A2: Kolom 'Punya sekarang' ditarik otomatis dari tab Komparatif. Bobot di sel kuning boleh diubah.
A4: PROFIL LOMBA
A5: Jarak (km) | B5: 30
A6: Elevation gain (m) | B6: 1800
A7: Flat-equivalent (km) | B7: =B5+B6/100 | C7: Naismith: 100 m tanjakan = 1 km datar
A8: Cut-off time | B8: 0.41666667 | C8: Jam
A9: Water station | B9: 4-5 | C9: titik, jarak antar titik 5-8 km
A11: SKOR KESIAPAN
A12: Dimensi | B12: Punya sekarang | C12: Butuh untuk lomba | D12: Kesiapan | E12: Bobot | F12: Keterangan
A13: Jarak lari terjauh (km) | B13: =MAX(Komparatif!AI5:AI22) | C13: =B5 | D13: =IF(C13=0,0,MIN(1,B13/C13)) | E13: 0.3 | F13: Lari jalanan terjauh: 18 Agu. Lomba 4,7x lebih jauh.
A14: Elevation gain terbesar (m) | B14: =MAX(Komparatif!AA5:AA22) | C14: =B6 | D14: =IF(C14=0,0,MIN(1,B14/C14)) | E14: 0.3 | F14: Hiking Wonosobo 30 Agu. Lomba 3,5x lebih tinggi.
A15: Waktu di kaki terlama (jam) | B15: =MAX(Komparatif!AJ5:AJ22)*24 | C15: 9.03 | D15: =IF(C15=0,0,MIN(1,B15/C15)) | E15: 0.25 | F15: Wonosobo 30 Agu, total waktu di lintasan. Dimensi terkuatmu.
A16: Jumlah sesi trail | B16: =COUNTIFS(Komparatif!$F$5:$F$22,"Trail") | C16: 8 | D16: =IF(C16=0,0,MIN(1,B16/C16)) | E16: 0.15 | F16: Nol. Semua 15 sesi lari berlangsung di aspal Jakarta yang datar.
A17: SKOR GABUNGAN | D17: =SUMPRODUCT(D13:D16,E13:E16) | E17: =SUM(E13:E16) | F17: Bobot boleh diubah di sel kuning; skor gabungan ikut menyesuaikan.
A19: YANG SUDAH KUAT (bukan pembatas)
A20: Metrik | B20: Nilai | C20: Sesi | D20: Baca
A21: PR 5K | B21: =Komparatif!I22 | C21: 14 Sep | D21: Turun 22 menit dari 21 Juli.
A22: Pace 5K terbaik | B22: =Komparatif!J22 | C22: 14 Sep | D22: 8:00/km - flat-equivalent 48 km jadi lebih terjangkau.
A23: Cadence | B23: =Komparatif!Q22 | C23: 14 Sep | D23: 167 spm, stabil di 161-168 sejak 26 Agu.
A24: Stride | B24: =Komparatif!T22 | C24: 14 Sep | D24: 0,750 m - baru pecah dari plateau dua bulan.
A25: Waktu di kaki | B25: =MAX(Komparatif!AJ5:AJ22) | C25: 30 Agu | D25: 6,5 jam di lintasan - modal nyata untuk lomba 9 jam.
A27: KESIMPULAN
A28: - Kecepatan 5K bukan pembatasmu - dan memperbaikinya lagi hampir tidak memindahkan proyeksi GTR.
A29: - Di skenario B, tanjakan memakan 5 jam 9 menit dari 8 jam 39 menit waktu bergerak. Yang menentukan adalah VAM (laju mendaki), bukan pace datar.
A30: - Tiga dimensi pembatas - jarak, elevasi, dan pengalaman trail - tidak bergerak sama sekali sejak Juli.
A31: - Lima sesi terakhir semuanya 5K aspal. Untuk GTR, saat ini kamu melatih dimensi yang bukan pembatasnya.
A32: - ACWR 0,57 berarti tubuh sedang punya ruang menerima beban. Ini momen paling tepat memulai minggu 1 program 16 minggu.

Sheet Proyeksi GTR
A1: Proyeksi Waktu Finis & Strategi Lomba
A2: Sel kuning adalah input - ubah untuk melihat dampaknya pada waktu finis.
A4: ASUMSI PROFIL LINTASAN
A5: Total jarak (km) | B5: 30
A6: Total elevation gain (m) | B6: 1800
A7: Jarak menanjak (km) | B7: 10
A8: Jarak menurun (km) | B8: 10
A9: Jarak datar / rolling (km) | B9: 10
A10: COT (jam) | B10: 10
A11: Profil resmi lomba belum tersedia - pembagian 10/10/10 km adalah asumsi.
A13: TIGA SKENARIO
A14: Skenario | B14: VAM (m/jam) | C14: Pace turun /km | D14: Pace datar /km | E14: Waktu tanjakan | F14: Waktu turun | G14: Waktu datar | H14: Total + WS | I14: Margin COT
A15: A - tanpa perubahan latihan | B15: 280 | C15: 0.0079861111 | D15: 0.0086805556 | E15: =$B$6/B15/24 | F15: =C15*$B$8 | G15: =D15*$B$9 | H15: =E15+F15+G15+34/1440 | I15: =($B$10/24-H15)*1440
A16: B - realistis (target) | B16: 350 | C16: 0.0069444444 | D16: 0.0076388889 | E16: =$B$6/B16/24 | F16: =C16*$B$8 | G16: =D16*$B$9 | H16: =E16+F16+G16+23/1440 | I16: =($B$10/24-H16)*1440
A17: C - optimal | B17: 430 | C17: 0.0060763889 | D17: 0.0065972222 | E17: =$B$6/B17/24 | F17: =C17*$B$8 | G17: =D17*$B$9 | H17: =E17+F17+G17+18/1440 | I17: =($B$10/24-H17)*1440
A18: Waktu berhenti di WS sudah termasuk di kolom Total: A = 34 menit, B = 23 menit, C = 18 menit.
A19: VAM dasar diambil dari lap mendaki Wonosobo: 215-250 m/jam pada HR 108-125.
A21: RENCANA WATER STATION (skenario B)
A22: Titik | B22: KM | C22: Tiba | D22: Berhenti (mnt) | E22: Berangkat | F22: Batas mundur | G22: Minum (L) | H22: Kalori | I22: Aksi
A23: WS 1 | B23: 6 | C23: 0.064583333 | D23: 3 | E23: =IF(D23=0,"",C23+D23/1440) | F23: 0.076388889 | G23: 0.9 | H23: 350 | I23: Isi botol, 1 gel
A24: WS 2 | B24: 12 | C24: 0.1375 | D24: 5 | E24: =IF(D24=0,"",C24+D24/1440) | F24: 0.15972222 | G24: 1 | H24: 400 | I24: Makan padat + elektrolit
A25: WS 3 | B25: 18 | C25: 0.21597222 | D25: 6 | E25: =IF(D25=0,"",C25+D25/1440) | F25: 0.24305556 | G25: 1.1 | H25: 450 | I25: Titik kritis - makan penuh, cek kaki
A26: WS 4 | B26: 24 | C26: 0.29722222 | D26: 6 | E26: =IF(D26=0,"",C26+D26/1440) | F26: 0.32638889 | G26: 1.1 | H26: 450 | I26: Isi penuh terakhir
A27: WS 5 | B27: 28 | C27: 0.35 | D27: 3 | E27: =IF(D27=0,"",C27+D27/1440) | F27: 0.38194444 | G27: 0.7 | H27: 290 | I27: Top-up saja, jangan lama
A28: Finish | B28: 30 | C28: 0.37638889 | D28: 0 | E28: =IF(D28=0,"",C28+D28/1440) | F28: 0.41666667 | G28: 0.35 | H28: 150 | I28: -
A29: TOTAL | D29: =SUM(D23:D28) | G29: =SUM(G23:G28) | H29: =SUM(H23:H28)
A31: Batas mundur = jam maksimum berangkat dari titik itu agar COT masih terkejar.
A32: Logistik diturunkan dari sweat rate sesi sendiri (950 ml/jam pada 31 C) dan kalori Wonosobo (304 kkal/jam).
A33: PERINGATAN: proyeksi ini ekstrapolasi 4,7x di luar lari terjauh dan 3,5x di luar elevasi terbesar. Rentang error lebar.
