Workbook

Sheet Ringkasan
A1: Garmin Connect — Hiking & Trail Running (25 aktivitas)
A2: Sumber: Garmin Connect, ditarik 17 September 2026. Satuan asli akun imperial (mi/ft/°F); kolom metrik hasil konversi. 'Avg Pace 0 /mi' memang begitu di Garmin untuk aktivitas hiking — bukan data hilang.
A4: No | B4: Tanggal | C4: Jam | D4: Nama Aktivitas | E4: Tipe | F4: Jarak (km) | G4: Jarak (mi) | H4: Waktu | I4: Moving Time | J4: Elapsed | K4: Avg Pace (asli) | L4: Avg Moving Pace /km | M4: Best Pace /km | N4: Avg HR | O4: Max HR | P4: Ascent (m) | Q4: Descent (m) | R4: Min Elev (m) | S4: Max Elev (m) | T4: Avg Cadence | U4: Max Cadence | V4: Avg Power (W) | W4: Kalori | X4: Aerobic TE | Y4: Anaerobic TE | Z4: Avg Temp (°C) | AA4: Intensity Min | AB4: Body Battery | AC4: Self Eval | AD4: Perceived Effort
A5: 1 | B5: 2025-01-24 | C5: 11:21 AM | D5: Kerinci Hiking | E5: HIKING | F5: 8.58 | G5: 5.33 | H5: 0.24810185 | I5: 0.054247685 | J5: 0.24810185 | K5: 0 /mi | L5: 0.0063215856 | M5: 0.0057174769 | N5: 148 | O5: 181 | P5: 775 | Q5: 841 | R5: 1408 | S5: 2115 | T5: 11 | U5: 250 | W5: 2061 | X5: 5.0 Overreaching | Y5: 1.1 Some Benefit | Z5: 26.7 | AA5: 317 | AB5: 0
A6: 2 | B6: 2025-01-25 | C6: 10:15 AM | D6: Kerinci Hiking | E6: HIKING | F6: 9.17 | G6: 5.7 | H6: 0.39710648 | I6: 0.011226852 | J6: 0.39929398 | K6: 0 /mi | L6: 0.0012226042 | M6: 0.0054154282 | N6: 145 | O6: 173 | P6: 1488 | Q6: 16 | R6: 1820 | S6: 3305 | T6: 2 | U6: 187 | W6: 3121 | X6: 5.0 Overreaching | Y6: 1.0 Some Benefit | Z6: 20.9 | AA6: 474 | AB6: 0
A7: 3 | B7: 2025-01-26 | C7: 1:44 PM | D7: Hiking | E7: HIKING | F7: 0.03 | G7: 0.02 | H7: 0.059756944 | I7: 0.00038194444 | J7: 0.059814815 | K7: 0 /mi | L7: 0.011981528 | M7: 0.0079469329 | P7: 0 | Q7: 186 | R7: 3071 | S7: 3299 | T7: 1 | U7: 158 | W7: 2 | X7: 0.4 No Benefit | Y7: 0.0 No Benefit | Z7: 28
A8: 4 | B8: 2025-01-26 | C8: 3:17 PM | D8: Hiking | E8: HIKING | F8: 0.23 | G8: 0.14 | H8: 0.15108796 | I8: 0.0023958333 | J8: 0.15108796 | K8: 0 /mi | L8: 0.010284271 | M8: 0.0068178241 | N8: 144 | O8: 159 | P8: 0 | Q8: 847 | R8: 2204 | S8: 3058 | T8: 3 | U8: 176 | W8: 1319 | X8: 4.2 Highly Impacting | Y8: 0.0 No Benefit | Z8: 23 | AA8: 197 | AB8: -33
A9: 5 | B9: 2025-01-26 | C9: 7:06 PM | D9: Kerinci Hiking | E9: HIKING | F9: 0.6 | G9: 0.37 | H9: 0.083877315 | I9: 0.0034259259 | J9: 0.083877315 | K9: 0 /mi | L9: 0.0056959028 | M9: 0.0039914468 | N9: 142 | O9: 161 | P9: 0 | Q9: 397 | R9: 1801 | S9: 2203 | T9: 5 | U9: 187 | W9: 735 | X9: 4.0 Highly Impacting | Y9: 0.2 No Benefit | Z9: 24 | AA9: 109 | AB9: -1
A10: 6 | B10: 2025-02-01 | C10: 10:58 AM | D10: Bogor Hiking | E10: HIKING | F10: 2.95 | G10: 1.83 | H10: 0.071087963 | I10: 0.019155093 | J10: 0.071087963 | K10: 55:46 /mi | L10: 0.0064870023 | M10: 0.0047537731 | N10: 119 | O10: 150 | P10: 201 | Q10: 35 | R10: 1101 | S10: 1268 | T10: 23 | U10: 209 | W10: 456 | X10: 1.7 Some Benefit | Y10: 0.0 No Benefit | Z10: 28 | AA10: 54 | AB10: -8
A11: 7 | B11: 2025-04-05 | C11: 10:24 AM | D11: Purwakarta Hiking | E11: HIKING | F11: 2.56 | G11: 1.59 | H11: 0.19123843 | I11: 0.0092476852 | J11: 0.19618056 | K11: 0 /mi | L11: 0.0036246644 | M11: 0.0056096065 | N11: 132 | O11: 171 | P11: 198 | Q11: 202 | R11: 432 | S11: 632 | T11: 5 | U11: 240 | W11: 1353 | X11: 3.7 Impacting | Y11: 2.2 Maintaining | Z11: 38 | AA11: 176 | AB11: -24
A12: 8 | B12: 2025-05-29 | C12: 9:50 AM | D12: Magelang Hiking | E12: HIKING | F12: 6.86 | G12: 4.26 | H12: 0.29920139 | I12: 0.01412037 | J12: 0.30018519 | K12: 0 /mi | L12: 0.0020640509 | M12: 0.0067746759 | N12: 140 | O12: 174 | P12: 1210 | Q12: 6 | R12: 1527 | S12: 2743 | T12: 7 | U12: 160 | W12: 2417 | X12: 5.0 Overreaching | Y12: 1.7 Some Benefit | Z12: 30.3 | AA12: 354 | AB12: -18
A13: 9 | B13: 2025-05-30 | C13: 10:53 AM | D13: Magelang Hiking | E13: HIKING | F13: 5.38 | G13: 3.34 | H13: 0.16293981 | I13: 0.030810185 | J13: 0.16564815 | K13: 0 /mi | L13: 0.0057390509 | M13: 0.0053003588 | N13: 140 | O13: 165 | P13: 2 | Q13: 1219 | R13: 1524 | S13: 2743 | T13: 20 | U13: 240 | W13: 1370 | X13: 4.5 Highly Impacting | Y13: 0.0 No Benefit | Z13: 29.4 | AA13: 205
A14: 10 | B14: 2025-05-30 | C14: 4:11 AM | D14: Magelang Hiking | E14: HIKING | F14: 2.43 | G14: 1.51 | H14: 0.11978009 | I14: 0.0048148148 | J14: 0.11982639 | K14: 0 /mi | L14: 0.0019777431 | M14: 0.0039914468 | N14: 137 | O14: 171 | P14: 426 | Q14: 29 | R14: 2742 | S14: 3157 | T14: 4 | U14: 188 | W14: 961 | X14: 4.1 Highly Impacting | Y14: 1.9 Some Benefit | Z14: 24 | AB14: -15
A15: 11 | B15: 2025-05-30 | C15: 8:05 AM | D15: Magelang Hiking | E15: HIKING | F15: 1.13 | G15: 0.7 | H15: 0.042303241 | I15: 0.010324074 | J15: 0.042326389 | K15: 0 /mi | L15: 0.0091623495 | M15: 0.0043366551 | N15: 139 | O15: 155 | P15: 1 | Q15: 310 | R15: 2746 | S15: 3060 | T15: 21 | U15: 162 | W15: 410 | X15: 3.1 Impacting | Y15: 0.0 No Benefit | Z15: 27 | AB15: 0
A16: 12 | B16: 2025-08-16 | C16: 10:24 AM | D16: Pemalang Hiking | E16: HIKING | F16: 5.34 | G16: 3.32 | H16: 0.22700231 | I16: 0.013414352 | J16: 0.22704861 | K16: 0 /mi | L16: 0.0025099421 | M16: 0.0053003588 | N16: 131 | O16: 173 | P16: 865 | Q16: 4 | R16: 1952 | S16: 2814 | T16: 10 | U16: 167 | W16: 1677 | X16: 4.3 Highly Impacting | Y16: 2.4 Maintaining | Z16: 27 | AA16: 240 | AB16: 0
A17: 13 | B17: 2025-08-17 | C17: 11:18 AM | D17: Pemalang Hiking | E17: HIKING | F17: 3.69 | G17: 2.29 | H17: 0.12783565 | I17: 0.018726852 | J17: 0.12792824 | K17: 0 /mi | L17: 0.0050774074 | M17: 0.0064941898 | N17: 120 | O17: 145 | P17: 0 | Q17: 857 | R17: 1963 | S17: 2824 | T17: 20 | U17: 158 | W17: 784 | X17: 3.0 Impacting | Y17: 0.0 No Benefit | Z17: 27 | AA17: 74 | AB17: 0
A18: 14 | B18: 2025-08-17 | C18: 3:17 AM | D18: Pemalang Hiking | E18: HIKING | F18: 2.53 | G18: 1.57 | H18: 0.15111111 | I18: 0.0036226852 | J18: 0.15111111 | K18: 0 /mi | L18: 0.0014383565 | M18: 0.0064654282 | N18: 130 | O18: 170 | P18: 627 | Q18: 2 | R18: 2815 | S18: 3443 | T18: 5 | U18: 167 | W18: 1073 | X18: 3.2 Impacting | Y18: 0.8 No Benefit | Z18: 21 | AA18: 137 | AB18: 0
A19: 15 | B19: 2025-08-17 | C19: 7:12 AM | D19: Pemalang Hiking | E19: HIKING | F19: 2.25 | G19: 1.4 | H19: 0.084143519 | I19: 0.0088541667 | J19: 0.084189815 | K19: 0 /mi | L19: 0.0039195255 | M19: 0.0051277546 | N19: 127 | O19: 153 | P19: 5 | Q19: 584 | R19: 2823 | S19: 3436 | T19: 12 | U19: 214 | W19: 604 | X19: 3.0 Impacting | Y19: 0.3 No Benefit | Z19: 29 | AA19: 75 | AB19: 0
A20: 16 | B20: 2025-12-20 | C20: 12:00 PM | D20: Bogor Hiking | E20: HIKING | F20: 7.44 | G20: 4.62 | H20: 0.10322917 | I20: 0.078703704 | J20: 0.10322917 | K20: 32:12 /mi | L20: 0.010586319 | M20: 0.0051277546 | N20: 134 | O20: 161 | P20: 89 | Q20: 498 | R20: 757 | S20: 1202 | T20: 76 | U20: 244 | W20: 791 | X20: 3.4 Impacting | Y20: 0.0 No Benefit | Z20: 26 | AA20: 116 | AB20: 0
A21: 17 | B21: 2025-12-20 | C21: 8:33 AM | D21: Bogor Hiking | E21: HIKING | F21: 7.58 | G21: 4.71 | H21: 0.11763889 | I21: 0.078240741 | J21: 0.11763889 | K21: 35:57 /mi | L21: 0.010313032 | M21: 0.0059907639 | N21: 137 | O21: 170 | P21: 500 | Q21: 86 | R21: 744 | S21: 1199 | T21: 55 | U21: 240 | W21: 903 | X21: 3.8 Impacting | Y21: 0.0 No Benefit | Z21: 26 | AA21: 125 | AB21: -5
A22: 18 | B22: 2025-12-27 | C22: 4:54 PM | D22: Bogor Hiking | E22: HIKING | F22: 13.79 | G22: 8.57 | H22: 0.17280093 | I22: 0.11972222 | J22: 0.20256944 | K22: 29:04 /mi | L22: 0.0086804977 | M22: 0.0044445255 | N22: 145 | O22: 170 | P22: 472 | Q22: 968 | R22: 269 | S22: 1100 | T22: 71 | U22: 250 | W22: 1517 | X22: 4.8 Highly Impacting | Y22: 1.0 Some Benefit | Z22: 28 | AA22: 234 | AB22: -11
A23: 19 | B23: 2026-01-17 | C23: 7:43 AM | D23: Bogor - Easy Run | E23: TRAIL RUNNING | F23: 15.29 | G23: 9.5 | H23: 0.33990741 | I23: 0.14728009 | J23: 0.39194444 | K23: 51:29 /mi | L23: 0.0096370023 | M23: 0.003531169 | N23: 139 | O23: 170 | P23: 1238 | Q23: 1213 | R23: 352 | S23: 922 | T23: 34 | U23: 238 | V23: 34 | W23: 2748 | X23: 4.3 Highly Impacting | Y23: 1.2 Some Benefit | Z23: 28.9 | AA23: 405 | AB23: -2 | AC23: Very Strong | AD23: 8/10 Very Hard
A24: 20 | B24: 2026-01-23 | C24: 5:42 AM | D24: Bogor Trail Running | E24: TRAIL RUNNING | F24: 3.88 | G24: 2.41 | H24: 0.039594907 | I24: 0.035300926 | J24: 0.057893519 | K24: 23:40 /mi | L24: 0.0091120023 | M24: 0.0021287731 | N24: 124 | O24: 152 | P24: 101 | Q24: 65 | R24: 651 | S24: 714 | T24: 99 | U24: 188 | V24: 110 | W24: 306 | X24: 1.7 Some Benefit | Y24: 0.0 No Benefit | Z24: 25.2 | AA24: 42 | AB24: -5 | AC24: Very Strong | AD24: 1/10 Very Light
A25: 21 | B25: 2026-04-11 | C25: 8:27 AM | D25: Bogor Trail Running | E25: TRAIL RUNNING | F25: 26.41 | G25: 16.41 | H25: 0.34876157 | I25: 0.26440972 | J25: 0.46435185 | K25: 30:37 /mi | L25: 0.010010984 | M25: 0.0039914468 | N25: 140 | O25: 172 | P25: 1209 | Q25: 1224 | R25: 721 | S25: 1332 | T25: 70 | U25: 250 | V25: 74 | W25: 2790 | X25: 3.4 Impacting | Y25: 0.1 No Benefit | Z25: 27.1 | AA25: 413 | AB25: -7 | AC25: Very Strong | AD25: 6/10 Hard
A26: 22 | B26: 2026-04-30 | C26: 8:07 PM | D26: Bogor Trail Running | E26: TRAIL RUNNING | F26: 14.32 | G26: 8.9 | H26: 0.1528125 | I26: 0.14652778 | J26: 0.1697338 | K26: 24:43 /mi | L26: 0.010226736 | M26: 0.0043654167 | N26: 134 | O26: 170 | P26: 573 | Q26: 566 | R26: 758 | S26: 1203 | T26: 94 | U26: 250 | V26: 98 | W26: 1172 | X26: 2.9 Maintaining | Y26: 0.1 No Benefit | Z26: 25.9 | AA26: 182 | AB26: -11 | AC26: Very Strong | AD26: 4/10 Somewhat Hard
A27: 23 | B27: 2026-08-30 | C27: 10:49 AM | D27: Wonosobo Trail Running | E27: TRAIL RUNNING | F27: 8.13 | G27: 5.05 | H27: 0.25393519 | I27: 0.079421296 | J27: 0.26819444 | K27: 0 /mi | L27: 0.0097664583 | M27: 0.0046818634 | N27: 146 | O27: 180 | P27: 549 | Q27: 768 | R27: 1994 | S27: 2605 | T27: 29 | U27: 244 | V27: 26 | W27: 1998 | X27: 4.3 Highly Impacting | Y27: 0.7 No Benefit | Z27: 27.3 | AA27: 316 | AB27: 0 | AC27: Normal | AD27: 1/10 Very Light
A28: 24 | B28: 2026-09-05 | C28: 10:56 AM | D28: Wonosobo Hiking | E28: HIKING | F28: 5.92 | G28: 3.68 | H28: 0.2365625 | I28: 0.023113426 | J28: 0.31898148 | K28: 0 /mi | L28: 0.0039051505 | M28: 0.0054154282 | N28: 149 | O28: 186 | P28: 1026 | Q28: 15 | R28: 1273 | S28: 2833 | T28: 15 | U28: 214 | W28: 2294 | X28: 5.0 Overreaching | Y28: 2.1 Maintaining | Z28: 27 | AA28: 477 | AB28: -14
A29: 25 | B29: 2026-09-06 | C29: 1:33 PM | D29: Wonosobo Hiking | E29: HIKING | F29: 4.8 | G29: 2.98 | H29: 0.13875 | I29: 0.037164352 | J29: 0.14587963 | K29: 0 /mi | L29: 0.0077599537 | M29: 0.0063000116 | N29: 132 | O29: 165 | P29: 12 | Q29: 1050 | R29: 1268 | S29: 2780 | T29: 25 | U29: 188 | W29: 1012 | X29: 3.0 Impacting | Y29: 0.1 No Benefit | Z29: 23 | AA29: 153 | AB29: 0
D30: TOTAL | F30: =SUM(F5:F29) -> 161.29 | G30: =SUM(G5:G29) -> 100.2 | H30: =SUM(H5:H29) -> 4.3205671 | P30: =SUM(P5:P29) -> 11567 | Q30: =SUM(Q5:Q29) -> 11988 | W30: =SUM(W5:W29) -> 33874
A32: Kuning = Hiking · Biru = Trail Running

Sheet Detail Lap
A1: Detail Lap / Interval per Aktivitas
A2: Baris Summary dari Garmin ikut disertakan dan ditandai. Aktivitas 17 Jan 2026 memakai tab Intervals (workout terstruktur), jadi punya kolom Step Type.
A4: Tanggal | B4: Nama Aktivitas | C4: Tipe | D4: Lap/Interval | E4: Step Type | F4: Waktu | G4: Cumulative | H4: Jarak (km) | I4: Jarak (mi) | J4: Avg Pace (asli) | K4: Avg HR | L4: Max HR | M4: Ascent (m) | N4: Descent (m) | O4: Avg Power (W) | P4: Cadence | Q4: Kalori | R4: Best Pace | S4: Moving Time | T4: Avg Moving Pace
A5: 2025-01-24 | B5: Kerinci Hiking | C5: HIKING | D5: 1 | F5: 0.14917824 | G5: 0.14917824 | H5: 4.31 | I5: 2.68 | J5: 0 | K5: 149 | L5: 181 | M5: 770 | N5: 131 | P5: 7 | Q5: 1402 | R5: 13:15 | S5: 0.016134259 | T5: 8:41
A6: 2025-01-24 | B6: Kerinci Hiking | C6: HIKING | D6: 2 | F6: 0.00016898148 | G6: 0.14935185 | H6: 0 | I6: 0 | J6: 0 | K6: 118 | L6: 120 | M6: 0 | N6: 0 | P6: 0 | Q6: 0 | R6: 0
A7: 2025-01-24 | B7: Kerinci Hiking | C7: HIKING | D7: 3 | F7: 0.03193287 | G7: 0.18128472 | H7: 0.9 | I7: 0.56 | J7: 0 | K7: 149 | L7: 160 | M7: 0 | N7: 224 | P7: 3 | Q7: 236 | R7: 16:43 | S7: 0.002650463 | T7: 6:51
A8: 2025-01-24 | B8: Kerinci Hiking | C8: HIKING | D8: 4 | F8: 0.066805556 | G8: 0.24810185 | H8: 3.38 | I8: 2.1 | J8: 45:56 | K8: 144 | L8: 163 | M8: 5 | N8: 486 | P8: 24 | Q8: 422 | R8: 13:57 | S8: 0.035462963 | T8: 24:22
A9: 2025-01-25 | B9: Kerinci Hiking | C9: HIKING | D9: 1 | F9: 0.014814815 | G9: 0.014814815 | H9: 0.85 | I9: 0.53 | J9: 39:58 | K9: 156 | L9: 173 | M9: 74 | N9: 0 | P9: 10 | Q9: 198 | R9: 14:27 | S9: 0.0025462963 | T9: 6:52
A10: 2025-01-25 | B10: Kerinci Hiking | C10: HIKING | D10: 2 | F10: 0.056759259 | G10: 0.071574074 | H10: 1.92 | I10: 1.19 | J10: 0 | K10: 153 | L10: 170 | M10: 314 | N10: 0 | P10: 4 | Q10: 619 | R10: 15:18 | S10: 0.0048958333 | T10: 5:54
A11: 2025-01-25 | B11: Kerinci Hiking | C11: HIKING | D11: 3 | F11: 0.32553241 | G11: 0.39710648 | H11: 6.41 | I11: 3.98 | J11: 0 | K11: 143 | L11: 169 | M11: 1100 | N11: 16 | P11: 2 | Q11: 2303 | R11: 12:33 | S11: 0.0037847222 | T11: 1:22
A12: 2025-01-26 | B12: Hiking | C12: HIKING | D12: 1 | F12: 0.059756944 | G12: 0.059756944 | H12: 0.03 | I12: 0.02 | J12: 0 | M12: 0 | N12: 186 | P12: 1 | Q12: 2 | R12: 18:25 | S12: 0.00038194444 | T12: 27:46
A13: 2025-01-26 | B13: Hiking | C13: HIKING | D13: 1 | F13: 0.15108796 | G13: 0.15108796 | H13: 0.23 | I13: 0.14 | J13: 0 | K13: 144 | L13: 159 | M13: 0 | N13: 847 | P13: 3 | Q13: 1319 | R13: 15:48 | S13: 0.0023958333 | T13: 23:50
A14: 2025-01-26 | B14: Kerinci Hiking | C14: HIKING | D14: 1 | F14: 0.083877315 | G14: 0.083877315 | H14: 0.6 | I14: 0.37 | J14: 0 | K14: 142 | L14: 161 | M14: 0 | N14: 397 | P14: 5 | Q14: 735 | R14: 9:15 | S14: 0.0034259259 | T14: 13:12
A15: 2025-02-01 | B15: Bogor Hiking | C15: HIKING | D15: 1 | F15: 0.071087963 | G15: 0.071087963 | H15: 2.95 | I15: 1.83 | J15: 55:46 | K15: 119 | L15: 150 | M15: 201 | N15: 35 | P15: 23 | Q15: 456 | R15: 11:01 | S15: 0.019155093 | T15: 15:02
A16: 2025-04-05 | B16: Purwakarta Hiking | C16: HIKING | D16: 1 | F16: 0.19123843 | G16: 0.19123843 | H16: 2.56 | I16: 1.59 | J16: 0 | K16: 132 | L16: 171 | M16: 198 | N16: 202 | P16: 5 | Q16: 1353 | R16: 13:00 | S16: 0.0092476852 | T16: 8:24
A17: 2025-05-29 | B17: Magelang Hiking | C17: HIKING | D17: 1 | F17: 0.18873843 | G17: 0.18873843 | H17: 4.2 | I17: 2.61 | J17: 0 | K17: 138 | L17: 174 | M17: 689 | N17: 3 | P17: 7 | Q17: 1454 | R17: 18:47 | S17: 0.0079166667 | T17: 4:22
A18: 2025-05-29 | B18: Magelang Hiking | C18: HIKING | D18: 2 | F18: 3.4722222e-05 | G18: 0.18877315 | H18: 0 | I18: 0 | J18: 0 | K18: 136 | L18: 136 | M18: 0 | N18: 0 | P18: 0 | Q18: 0 | R18: 0
A19: 2025-05-29 | B19: Magelang Hiking | C19: HIKING | D19: 3 | F19: 8.1018519e-06 | G19: 0.18878472 | H19: 0 | I19: 0 | J19: 0 | K19: 137 | L19: 137 | M19: 0 | N19: 0 | P19: 0 | Q19: 0 | R19: 0
A20: 2025-05-29 | B20: Magelang Hiking | C20: HIKING | D20: 4 | F20: 0.11041667 | G20: 0.29920139 | H20: 2.66 | I20: 1.65 | J20: 0 | K20: 144 | L20: 165 | M20: 521 | N20: 3 | P20: 8 | Q20: 963 | R20: 15:42 | S20: 0.0062037037 | T20: 5:25
A21: 2025-05-30 | B21: Magelang Hiking | C21: HIKING | D21: 1 | F21: 0.065451389 | G21: 0.065451389 | H21: 2.38 | I21: 1.48 | J21: 0 | K21: 147 | L21: 165 | M21: 2 | N21: 569 | P21: 25 | Q21: 614 | R21: 13:04 | S21: 0.01412037 | T21: 13:47
A22: 2025-05-30 | B22: Magelang Hiking | C22: HIKING | D22: 2 | F22: 7.7546296e-05 | G22: 0.065532407 | H22: 0 | I22: 0 | J22: 0 | M22: 0 | N22: 0 | P22: 0 | Q22: 0 | R22: 0
A23: 2025-05-30 | B23: Magelang Hiking | C23: HIKING | D23: 3 | F23: 0.097407407 | G23: 0.16293981 | H23: 2.99 | I23: 1.86 | J23: 0 | K23: 135 | L23: 157 | M23: 0 | N23: 650 | P23: 16 | Q23: 757 | R23: 12:17 | S23: 0.016689815 | T23: 12:55
A24: 2025-05-30 | B24: Magelang Hiking | C24: HIKING | D24: 1 | F24: 0.11978009 | G24: 0.11978009 | H24: 2.43 | I24: 1.51 | J24: 0 | K24: 137 | L24: 171 | M24: 426 | N24: 29 | P24: 4 | Q24: 961 | R24: 9:15 | S24: 0.0048148148 | T24: 4:35
A25: 2025-05-30 | B25: Magelang Hiking | C25: HIKING | D25: 1 | F25: 0.042303241 | G25: 0.042303241 | H25: 1.13 | I25: 0.7 | J25: 0 | K25: 139 | L25: 155 | M25: 1 | N25: 310 | P25: 21 | Q25: 410 | R25: 10:03 | S25: 0.010324074 | T25: 21:14
A26: 2025-08-16 | B26: Pemalang Hiking | C26: HIKING | D26: 1 | F26: 0.22700231 | G26: 0.22700231 | H26: 5.34 | I26: 3.32 | J26: 0 | K26: 131 | L26: 173 | M26: 865 | N26: 4 | P26: 10 | Q26: 1677 | R26: 12:17 | S26: 0.013414352 | T26: 5:49
A27: 2025-08-17 | B27: Pemalang Hiking | C27: HIKING | D27: 1 | F27: 0.12783565 | G27: 0.12783565 | H27: 3.69 | I27: 2.29 | J27: 0 | K27: 120 | L27: 145 | M27: 0 | N27: 857 | P27: 20 | Q27: 784 | R27: 15:03 | S27: 0.018726852 | T27: 11:46
A28: 2025-08-17 | B28: Pemalang Hiking | C28: HIKING | D28: 1 | F28: 0.15111111 | G28: 0.15111111 | H28: 2.53 | I28: 1.57 | J28: 0 | K28: 130 | L28: 170 | M28: 627 | N28: 2 | P28: 5 | Q28: 1073 | R28: 14:59 | S28: 0.0036226852 | T28: 3:20
A29: 2025-08-17 | B29: Pemalang Hiking | C29: HIKING | D29: 1 | F29: 0.084143519 | G29: 0.084143519 | H29: 2.25 | I29: 1.4 | J29: 0 | K29: 127 | L29: 153 | M29: 5 | N29: 584 | P29: 12 | Q29: 604 | R29: 11:53 | S29: 0.0088541667 | T29: 9:05
A30: 2025-12-20 | B30: Bogor Hiking | C30: HIKING | D30: 1 | F30: 0.10322917 | G30: 0.10322917 | H30: 7.44 | I30: 4.62 | J30: 32:12 | K30: 134 | L30: 161 | M30: 89 | N30: 498 | P30: 76 | Q30: 791 | R30: 11:53 | S30: 0.078703704 | T30: 24:32
A31: 2025-12-20 | B31: Bogor Hiking | C31: HIKING | D31: 1 | F31: 0.11763889 | G31: 0.11763889 | H31: 7.58 | I31: 4.71 | J31: 35:57 | K31: 137 | L31: 170 | M31: 500 | N31: 86 | P31: 55 | Q31: 903 | R31: 13:53 | S31: 0.078240741 | T31: 23:54
A32: 2025-12-27 | B32: Bogor Hiking | C32: HIKING | D32: 1 | F32: 0.17280093 | G32: 0.17280093 | H32: 13.79 | I32: 8.57 | J32: 29:04 | K32: 145 | L32: 170 | M32: 472 | N32: 968 | P32: 71 | Q32: 1517 | R32: 10:18 | S32: 0.11972222 | T32: 20:07
A33: 2026-01-17 | B33: Bogor - Easy Run | C33: TRAIL RUNNING | D33: 1 | E33: Warm Up | F33: 0.0034722222 | G33: 0.0034722222 | H33: 0.29 | I33: 0.18 | J33: 28:10 | K33: 118 | L33: 137 | M33: 23 | N33: 1 | O33: 91 | P33: 66 | Q33: 26 | R33: 8:11 | S33: 0.0032175926
A34: 2026-01-17 | B34: Bogor - Easy Run | C34: TRAIL RUNNING | D34: 2 | E34: Run | F34: 0.0069444444 | G34: 0.010416667 | H34: 0.42 | I34: 0.26 | J34: 38:56 | K34: 142 | L34: 164 | M34: 68 | N34: 0 | O34: 66 | P34: 39 | Q34: 84 | R34: 17:06 | S34: 0.0049884259
A35: 2026-01-17 | B35: Bogor - Easy Run | C35: TRAIL RUNNING | D35: 3 | E35: Run | F35: 0.0069444444 | G35: 0.017361111 | H35: 0.24 | I35: 0.15 | J35: 0 | K35: 152 | L35: 157 | M35: 79 | N35: 0 | O35: 50 | P35: 24 | Q35: 95 | R35: 23:11 | S35: 0.0031828704
A36: 2026-01-17 | B36: Bogor - Easy Run | C36: TRAIL RUNNING | D36: 4 - 19 | E36: Cool Down | F36: 0.3225463 | G36: 0.33990741 | H36: 14.34 | I36: 8.91 | J36: 52:05 | K36: 139 | L36: 170 | M36: 1068 | N36: 1212 | O36: 33 | P36: 34 | Q36: 2,542 | R36: 10:05 | S36: 0.13586806
A37: 2026-01-17 | B37: Bogor - Easy Run | C37: TRAIL RUNNING | D37: 4 | E37: Cool Down | F37: 0.0034722222 | G37: 0.020833333 | H37: 0.11 | I37: 0.07 | J37: 0 | K37: 150 | L37: 161 | M37: 34 | N37: 0 | O37: 43 | P37: 20 | Q37: 44 | R37: 22:28 | S37: 0.0013773148
A38: 2026-01-17 | B38: Bogor - Easy Run | C38: TRAIL RUNNING | D38: 5 | E38: Cool Down | F38: 0.036215278 | G38: 0.057048611 | H38: 1 | I38: 0.62 | J38: 0 | K38: 143 | L38: 164 | M38: 281 | N38: 10 | O38: 29 | P38: 15 | Q38: 329 | R38: 18:19 | S38: 0.0052777778
A39: 2026-01-17 | B39: Bogor - Easy Run | C39: TRAIL RUNNING | D39: 6 | E39: Cool Down | F39: 0.032905093 | G39: 0.089953704 | H39: 1 | I39: 0.62 | J39: 0 | K39: 133 | L39: 163 | M39: 31 | N39: 254 | O39: 9 | P39: 15 | Q39: 246 | R39: 10:46 | S39: 0.0059953704
A40: 2026-01-17 | B40: Bogor - Easy Run | C40: TRAIL RUNNING | D40: 7 | E40: Cool Down | F40: 0.019421296 | G40: 0.109375 | H40: 1 | I40: 0.62 | J40: 45:00 | K40: 147 | L40: 165 | M40: 127 | N40: 24 | O40: 61 | P40: 44 | Q40: 189 | R40: 16:31 | S40: 0.013240741
A41: 2026-01-17 | B41: Bogor - Easy Run | C41: TRAIL RUNNING | D41: 8 | E41: Cool Down | F41: 0.019502315 | G41: 0.12887731 | H41: 1 | I41: 0.62 | J41: 45:09 | K41: 144 | L41: 167 | M41: 107 | N41: 21 | O41: 53 | P41: 43 | Q41: 162 | R41: 13:57 | S41: 0.013935185
...

Sheet Time in Zones
A1: Time in Zones — Heart Rate
A2: Rentang zona berubah seiring waktu karena Garmin menyesuaikan max HR — rentang per aktivitas ikut dicatat.
A4: Tanggal | B4: Nama Aktivitas | C4: Tipe | D4: Z5 rentang | E4: Z5 waktu | F4: Z5 % | G4: Z4 rentang | H4: Z4 waktu | I4: Z4 % | J4: Z3 rentang | K4: Z3 waktu | L4: Z3 % | M4: Z2 rentang | N4: Z2 waktu | O4: Z2 % | P4: Z1 rentang | Q4: Z1 waktu | R4: Z1 %
A5: 2025-01-24 | B5: Kerinci Hiking | C5: HIKING | D5: > 178 | E5: 0.00081018519 | F5: 0 | G5: 159-178 | H5: 0.04318287 | I5: 0.17 | J5: 139-158 | K5: 0.15690972 | L5: 0.63 | M5: 119-138 | N5: 0.043043981 | O5: 0.17 | P5: 100-118 | Q5: 0.0041203704 | R5: 0.01
A6: 2025-01-25 | B6: Kerinci Hiking | C6: HIKING | D6: > 178 | E6: 0 | F6: 0 | G6: 159-178 | H6: 0.069270833 | I6: 0.17 | J6: 139-158 | K6: 0.21087963 | L6: 0.53 | M6: 119-138 | N6: 0.1021875 | O6: 0.25 | P6: 100-118 | Q6: 0.014212963 | R6: 0.03
A7: 2025-01-26 | B7: Hiking | C7: HIKING | D7: — | E7: — | F7: — | G7: — | H7: — | I7: — | J7: — | K7: — | L7: — | M7: — | N7: — | O7: — | P7: — | Q7: — | R7: —
A8: 2025-01-26 | B8: Hiking | C8: HIKING | D8: > 178 | E8: 0 | F8: 0 | G8: 159-178 | H8: 3.4722222e-05 | I8: 0 | J8: 139-158 | K8: 0.1384838 | L8: 0.91 | M8: 119-138 | N8: 0.01255787 | O8: 0.08 | P8: 100-118 | Q8: 0 | R8: 0
A9: 2025-01-26 | B9: Kerinci Hiking | C9: HIKING | D9: > 178 | E9: 0 | F9: 0 | G9: 159-178 | H9: 0.001724537 | I9: 0.02 | J9: 139-158 | K9: 0.055555556 | L9: 0.66 | M9: 119-138 | N9: 0.026111111 | O9: 0.31 | P9: 100-118 | Q9: 0.00047453704 | R9: 0
A10: 2025-02-01 | B10: Bogor Hiking | C10: HIKING | D10: > 178 | E10: 0 | F10: 0 | G10: 159-178 | H10: 0 | I10: 0 | J10: 139-158 | K10: 0.0031481481 | L10: 0.04 | M10: 119-138 | N10: 0.031840278 | O10: 0.44 | P10: 100-118 | Q10: 0.03462963 | R10: 0.48
A11: 2025-04-05 | B11: Purwakarta Hiking | C11: HIKING | D11: > 178 | E11: 0 | F11: 0 | G11: 159-178 | H11: 0.0052314815 | I11: 0.02 | J11: 139-158 | K11: 0.060787037 | L11: 0.31 | M11: 119-138 | N11: 0.087858796 | O11: 0.45 | P11: 100-118 | Q11: 0.03400463 | R11: 0.17
A12: 2025-05-29 | B12: Magelang Hiking | C12: HIKING | D12: > 184 | E12: 0 | F12: 0 | G12: 165-184 | H12: 0.0092708333 | I12: 0.03 | J12: 144-164 | K12: 0.14612269 | L12: 0.48 | M12: 124-143 | N12: 0.078703704 | O12: 0.26 | P12: 103-123 | Q12: 0.06005787 | R12: 0.2
A13: 2025-05-30 | B13: Magelang Hiking | C13: HIKING | D13: > 184 | E13: 0 | F13: 0 | G13: 165-184 | H13: 2.3148148e-05 | I13: 0 | J13: 144-164 | K13: 0.10185185 | L13: 0.62 | M13: 124-143 | N13: 0.034131944 | O13: 0.2 | P13: 103-123 | Q13: 0.010717593 | R13: 0.06
A14: 2025-05-30 | B14: Magelang Hiking | C14: HIKING | D14: > 184 | E14: 0 | F14: 0 | G14: 165-184 | H14: 0.0023611111 | I14: 0.01 | J14: 144-164 | K14: 0.045601852 | L14: 0.38 | M14: 124-143 | N14: 0.039178241 | O14: 0.32 | P14: 103-123 | Q14: 0.032083333 | R14: 0.26
A15: 2025-05-30 | B15: Magelang Hiking | C15: HIKING | D15: > 184 | E15: 0 | F15: 0 | G15: 165-184 | H15: 0 | I15: 0 | J15: 144-164 | K15: 0.018449074 | L15: 0.43 | M15: 124-143 | N15: 0.017731481 | O15: 0.41 | P15: 103-123 | Q15: 0.0061226852 | R15: 0.14
A16: 2025-08-16 | B16: Pemalang Hiking | C16: HIKING | D16: > 183 | E16: 0 | F16: 0 | G16: 163-183 | H16: 0.017175926 | I16: 0.07 | J16: 143-162 | K16: 0.05556713 | L16: 0.24 | M16: 122-142 | N16: 0.074097222 | O16: 0.32 | P16: 102-121 | Q16: 0.058958333 | R16: 0.25
A17: 2025-08-17 | B17: Pemalang Hiking | C17: HIKING | D17: > 183 | E17: 0 | F17: 0 | G17: 163-183 | H17: 0 | I17: 0 | J17: 143-162 | K17: 0.0017592593 | L17: 0.01 | M17: 122-142 | N17: 0.052118056 | O17: 0.4 | P17: 102-121 | Q17: 0.065081019 | R17: 0.5
A18: 2025-08-17 | B18: Pemalang Hiking | C18: HIKING | D18: > 183 | E18: 0 | F18: 0 | G18: 163-183 | H18: 0.00023148148 | I18: 0 | J18: 143-162 | K18: 0.024270833 | L18: 0.16 | M18: 122-142 | N18: 0.095300926 | O18: 0.63 | P18: 102-121 | Q18: 0.02275463 | R18: 0.15
A19: 2025-08-17 | B19: Pemalang Hiking | C19: HIKING | D19: > 183 | E19: 0 | F19: 0 | G19: 163-183 | H19: 0 | I19: 0 | J19: 143-162 | K19: 0.011956019 | L19: 0.14 | M19: 122-142 | N19: 0.037997685 | O19: 0.45 | P19: 102-121 | Q19: 0.029675926 | R19: 0.35
... A29: 2026-09-06 | B29: Wonosobo Hiking | C29: HIKING | D29: > 193 | E29: 0 | F29: 0 | G29: 172-193 | H29: 0 | I29: 0 | J29: 151-171 | K29: 0.0014699074 | L29: 0.01 | M29: 129-150 | N29: 0.094398148 | O29: 0.68 | P29: 108-128 | Q29: 0.029502315 | R29: 0.21
A31: Aktivitas 26 Jan 2025 1:44 PM tidak punya data HR, jadi tidak ada Time in Zones.

Sheet Power Zones
A1: Power Zones — hanya Trail Running
A2: Running power baru terekam di aktivitas trail 2026. Persentase tidak berjumlah 100% karena sisa waktu ada di bawah Zone 1.
A4: Tanggal | B4: Nama Aktivitas | C4: PZ5 rentang | D4: PZ5 waktu | E4: PZ5 % | F4: PZ4 rentang | G4: PZ4 waktu | H4: PZ4 % | I4: PZ3 rentang | J4: PZ3 waktu | K4: PZ3 % | L4: PZ2 rentang | M4: PZ2 waktu | N4: PZ2 % | O4: PZ1 rentang | P4: PZ1 waktu | Q4: PZ1 %
A5: 2026-01-17 | B5: Bogor - Easy Run | C5: > 229 W | D5: 0.0090740741 | E5: 0.02 | F5: 200-229 W | G5: 0.0043634259 | H5: 0.01 | I5: 180-199 W | J5: 0.0029282407 | K5: 0 | L5: 160-179 W | M5: 0.0048611111 | N5: 0.01 | O5: 130-159 W | P5: 0.010405093 | Q5: 0.03
A6: 2026-01-23 | B6: Bogor Trail Running | C6: > 229 W | D6: 0.0014236111 | E6: 0.03 | F6: 200-229 W | G6: 0.0021875 | H6: 0.05 | I6: 180-199 W | J6: 0.0023958333 | K6: 0.06 | L6: 160-179 W | M6: 0.0031712963 | N6: 0.08 | O6: 130-159 W | P6: 0.0072106481 | Q6: 0.18
A7: 2026-04-11 | B7: Bogor Trail Running | C7: > 229 W | D7: 0.0077893519 | E7: 0.02 | F7: 200-229 W | G7: 0.0085185185 | H7: 0.02 | I7: 180-199 W | J7: 0.012326389 | K7: 0.03 | L7: 160-179 W | M7: 0.024456019 | N7: 0.07 | O7: 130-159 W | P7: 0.030416667 | Q7: 0.08
A8: 2026-04-30 | B8: Bogor Trail Running | C8: > 229 W | D8: 0.0028356481 | E8: 0.01 | F8: 200-229 W | G8: 0.0044791667 | H8: 0.02 | I8: 180-199 W | J8: 0.0055787037 | K8: 0.03 | L8: 160-179 W | M8: 0.0093634259 | N8: 0.06 | O8: 130-159 W | P8: 0.021840278 | Q8: 0.14
A9: 2026-08-30 | B9: Wonosobo Trail Running | C9: > 229 W | D9: 0.0027777778 | E9: 0.01 | F9: 200-229 W | G9: 0.0014930556 | H9: 0 | I9: 180-199 W | J9: 0.0019097222 | K9: 0 | L9: 160-179 W | M9: 0.0028703704 | N9: 0.01 | O9: 130-159 W | P9: 0.0086342593 | Q9: 0.03

Sheet Analisis
A1: Analisis — Hiking & Trail Running
A2: Semua angka formula yang menarik dari sheet Ringkasan & Time in Zones. Ubah datanya, angka di sini ikut berubah.
A4: A. TOTAL SEMUA AKTIVITAS (Jan 2025 – Sep 2026)
A5: Jumlah aktivitas | B5: =COUNTA(Ringkasan!$D$5:$D$29) -> 25
A6: Total jarak (km) | B6: =SUM(Ringkasan!$F$5:$F$29) -> 161.29
A7: Total waktu bergerak | B7: =SUM(Ringkasan!$H$5:$H$29) -> 4.3205671
A8: Total ascent (m) | B8: =SUM(Ringkasan!$P$5:$P$29) -> 11567 | F8: Sebagai gambaran: Puncak Kerinci 3.805 m dari permukaan laut.
A9: Total descent (m) | B9: =SUM(Ringkasan!$Q$5:$Q$29) -> 11988
A10: Total kalori (kcal) | B10: =SUM(Ringkasan!$W$5:$W$29) -> 33874
A12: B. HIKING vs TRAIL RUNNING
A13: Metrik | B13: Hiking | C13: Trail Running | D13: Selisih
A14: Jumlah aktivitas | B14: =COUNTIFS(Ringkasan!$E$5:$E$29,"HIKING") -> 20 | C14: =COUNTIFS(Ringkasan!$E$5:$E$29,"TRAIL RUNNING") -> 5 | D14: =C14-B14 -> -15
A15: Total jarak (km) | B15: =SUMIFS(Ringkasan!$F$5:$F$29,Ringkasan!$E$5:$E$29,"HIKING") -> 93.26 | C15: =SUMIFS(Ringkasan!$F$5:$F$29,Ringkasan!$E$5:$E$29,"TRAIL RUNNING") -> 68.03 | D15: =C15-B15 -> -25.23
A16: Rata-rata jarak (km) | B16: =AVERAGEIFS(Ringkasan!$F$5:$F$29,Ringkasan!$E$5:$E$29,"HIKING") -> 4.663 | C16: =AVERAGEIFS(Ringkasan!$F$5:$F$29,Ringkasan!$E$5:$E$29,"TRAIL RUNNING") -> 13.606 | D16: =C16-B16 -> 8.943
A17: Total waktu | B17: =SUMIFS(Ringkasan!$H$5:$H$29,Ringkasan!$E$5:$E$29,"HIKING") -> 3.1855556 | C17: =SUMIFS(Ringkasan!$H$5:$H$29,Ringkasan!$E$5:$E$29,"TRAIL RUNNING") -> 1.1350116 | D17: =C17-B17 -> -2.050544
A18: Rata-rata Avg HR | B18: =AVERAGEIFS(Ringkasan!$N$5:$N$29,Ringkasan!$E$5:$E$29,"HIKING") -> 136.36842 | C18: =AVERAGEIFS(Ringkasan!$N$5:$N$29,Ringkasan!$E$5:$E$29,"TRAIL RUNNING") -> 136.6 | D18: =C18-B18 -> 0.23157895
A19: Total ascent (m) | B19: =SUMIFS(Ringkasan!$P$5:$P$29,Ringkasan!$E$5:$E$29,"HIKING") -> 7897 | C19: =SUMIFS(Ringkasan!$P$5:$P$29,Ringkasan!$E$5:$E$29,"TRAIL RUNNING") -> 3670 | D19: =C19-B19 -> -4227
A20: Rata-rata kalori | B20: =AVERAGEIFS(Ringkasan!$W$5:$W$29,Ringkasan!$E$5:$E$29,"HIKING") -> 1243 | C20: =AVERAGEIFS(Ringkasan!$W$5:$W$29,Ringkasan!$E$5:$E$29,"TRAIL RUNNING") -> 1802.8 | D20: =C20-B20 -> 559.8
A22: C. PER LOKASI
A23: Lokasi | B23: Jumlah | C23: Total km | D23: Total ascent (m) | E23: Total jam
A24: Kerinci | B24: =COUNTIFS(Ringkasan!$D$5:$D$29,"*Kerinci*") -> 3 | C24: =SUMIFS(Ringkasan!$F$5:$F$29,Ringkasan!$D$5:$D$29,"*Kerinci*") -> 18.35 | D24: =SUMIFS(Ringkasan!$P$5:$P$29,Ringkasan!$D$5:$D$29,"*Kerinci*") -> 2263 | E24: =SUMIFS(Ringkasan!$H$5:$H$29,Ringkasan!$D$5:$D$29,"*Kerinci*") -> 0.72908565
A25: Magelang | B25: =COUNTIFS(Ringkasan!$D$5:$D$29,"*Magelang*") -> 4 | C25: =SUMIFS(Ringkasan!$F$5:$F$29,Ringkasan!$D$5:$D$29,"*Magelang*") -> 15.8 | D25: =SUMIFS(Ringkasan!$P$5:$P$29,Ringkasan!$D$5:$D$29,"*Magelang*") -> 1639 | E25: =SUMIFS(Ringkasan!$H$5:$H$29,Ringkasan!$D$5:$D$29,"*Magelang*") -> 0.62422454
A26: Pemalang | B26: =COUNTIFS(Ringkasan!$D$5:$D$29,"*Pemalang*") -> 4 | C26: =SUMIFS(Ringkasan!$F$5:$F$29,Ringkasan!$D$5:$D$29,"*Pemalang*") -> 13.81 | D26: =SUMIFS(Ringkasan!$P$5:$P$29,Ringkasan!$D$5:$D$29,"*Pemalang*") -> 1497 | E26: =SUMIFS(Ringkasan!$H$5:$H$29,Ringkasan!$D$5:$D$29,"*Pemalang*") -> 0.59009259
A27: Bogor | B27: =COUNTIFS(Ringkasan!$D$5:$D$29,"*Bogor*") -> 8 | C27: =SUMIFS(Ringkasan!$F$5:$F$29,Ringkasan!$D$5:$D$29,"*Bogor*") -> 91.66 | D27: =SUMIFS(Ringkasan!$P$5:$P$29,Ringkasan!$D$5:$D$29,"*Bogor*") -> 4383 | E27: =SUMIFS(Ringkasan!$H$5:$H$29,Ringkasan!$D$5:$D$29,"*Bogor*") -> 1.3458333
A28: Purwakarta | B28: =COUNTIFS(Ringkasan!$D$5:$D$29,"*Purwakarta*") -> 1 | C28: =SUMIFS(Ringkasan!$F$5:$F$29,Ringkasan!$D$5:$D$29,"*Purwakarta*") -> 2.56 | D28: =SUMIFS(Ringkasan!$P$5:$P$29,Ringkasan!$D$5:$D$29,"*Purwakarta*") -> 198 | E28: =SUMIFS(Ringkasan!$H$5:$H$29,Ringkasan!$D$5:$D$29,"*Purwakarta*") -> 0.19123843
A29: Wonosobo | B29: =COUNTIFS(Ringkasan!$D$5:$D$29,"*Wonosobo*") -> 3 | C29: =SUMIFS(Ringkasan!$F$5:$F$29,Ringkasan!$D$5:$D$29,"*Wonosobo*") -> 18.85 | D29: =SUMIFS(Ringkasan!$P$5:$P$29,Ringkasan!$D$5:$D$29,"*Wonosobo*") -> 1587 | E29: =SUMIFS(Ringkasan!$H$5:$H$29,Ringkasan!$D$5:$D$29,"*Wonosobo*") -> 0.62924769
A30: Catatan: 2 aktivitas 26 Jan 2025 hanya bernama "Hiking" tanpa lokasi, tapi rangkaian Kerinci — tidak terhitung di baris Kerinci.
A32: D. REKOR
A33: Ascent tertinggi (m) | B33: =MAX(Ringkasan!$P$5:$P$29) -> 1488 | F33: Kerinci 25 Jan 2025.
A34: Jarak terjauh (km) | B34: =MAX(Ringkasan!$F$5:$F$29) -> 26.41 | F34: Bogor Trail Running 11 Apr 2026.
A35: Durasi terlama | B35: =MAX(Ringkasan!$H$5:$H$29) -> 0.39710648 | F35: Kerinci 25 Jan 2025 — 9 jam 31 menit.
A36: Max HR tertinggi | B36: =MAX(Ringkasan!$O$5:$O$29) -> 186
A37: Kalori terbesar | B37: =MAX(Ringkasan!$W$5:$W$29) -> 3121
A38: Total jam Zone 3+ (aerobik ke atas) | B38: =SUM('Time in Zones'!$E$5:$E$29)+SUM('Time in Zones'!$H$5:$H$29)+SUM('Time in Zones'!$K$5:$K$29) -> 1.8438889 | F38: Z5+Z4+Z3 dijumlah dari semua aktivitas.
A40: E. CATATAN & TEMUAN
A41: 1. Total 25 aktivitas dalam 20 bulan: 20 Hiking + 5 Trail Running. Akumulasi ascent-nya besar sekali untuk aktivitas yang bukan latihan terstruktur.
A42: 2. Hampir semua aktivitas bertipe Base (Low Aerobic), dan mayoritas waktu ada di Zone 2. Ini pola aerobik volume tinggi — fondasi yang bagus untuk ultra/trail panjang.
A43: 3. Empat aktivitas kena Aerobic TE 5.0 Overreaching: Kerinci 24 & 25 Jan 2025, Magelang 29 Mei 2025, dan Wonosobo 5 Sep 2026. Semuanya pendakian panjang >5 jam.
A44: 4. Avg Pace sering tertulis 0 /mi di Garmin untuk hiking. Yang bisa dipakai adalah Avg Moving Pace — lihat kolomnya di sheet Ringkasan (sudah dikonversi ke /km).
A45: 5. Avg Cadence hiking sangat rendah (2-25 spm) karena jam mendeteksi langkah mendaki, bukan langkah lari. Jangan dibandingkan dengan cadence lari 160-170 spm di data COROS.
...
